Workbook
Name ListeKunden: OFFSET([1]Kundenübersicht!$E$4,0,0,MAX(ROW([1]Kundenübersicht!A1048576:A996)*([1]Kundenübersicht!A1048576:A996<>""))-3)

Sheet Tabelle1
V2: =SUMIF($I$4:$I$1494,"Hauswirtschaft",$V$4:$V$1494) -> 29130.375 | W2: =SUMIF($I$4:$I$1494,"Alltagsbegleitung",$V$4:$V$1494) -> 8410.5 | AE2: FILTER FÜR ABRECHNUNG! | AF2: FILTER FÜR ABRECHNUNG!
B3: Kunde | C3: Datum | D3: Start | E3: Ende | F3: Stunden | G3: Kilometer | H3: Senioren Engel | I3: Art | J3: Budget | K3: Pflegekasse - Name | L3: Pflegekasse - IK | M3: Versichertennummer | N3: Pflegegrad | P3: Durchgeführt | R3: Leistungsnachweis | S3: Ablage | U3: €/h | V3: Umsatz | W3: Umsatz Km | X3: Vertragstyp | Z3: Abgerechnet | AA3: Datum | AC3: Bezahlt | AE3: Monat/Jahr | AF3: Monat/Jahr | AG3: =H3 -> Senioren Engel | AJ3: Budgettopf
B4: 00001|Rosemarie|Schröder | C4: 45797 | D4: 0.41666667 | E4: 0.5 | F4: =(E4-D4)*24 -> 2 | H4: Celina Panther | I4: Hauswirtschaft | J4: Entlastungsleistung | K4: =VLOOKUP($B4,[1]Kundenübersicht!$E$4:$AC$1003,MATCH(K$3,[1]Kundenübersicht!$E$3:$BA$3,FALSE),FALSE) -> Barmer Pflegekasse | L4: =VLOOKUP(B4,[1]Kundenübersicht!$E$4:$AC$1003,MATCH(L$3,[1]Kundenübersicht!$E$3:$BA$3,FALSE),FALSE) -> 184940005 | M4: =VLOOKUP(B4,[1]Kundenübersicht!$E$4:$AC$1003,MATCH(M$3,[1]Kundenübersicht!$E$3:$BA$3,FALSE),FALSE) -> Z817157321 | N4: =VLOOKUP(B4,[1]Kundenübersicht!$E$4:$AC$1003,MATCH(N$3,[1]Kundenübersicht!$E$3:$BA$3,FALSE),FALSE) -> PG 1 | P4: Ja | R4: Unterschrieben | S4: Link | U4: =IF(YEAR(C4)<=2025,IFERROR(IF(I4="Hauswirtschaft",VLOOKUP($B4,[1]Kundenübersicht!$E$4:$BA$1003,MATCH("Hauswirtschaft [€/Stunde]",[1]Kundenübersicht!$E$3:$BA$3,FALSE),FALSE),VLOOKUP($B4,[1]Kundenübersicht!$E$4:$BA$1003,MATCH("Alltagsbegleitung [€/Stunde]",[1]Kundenübersicht!$E$3:$BA$3,FALSE),FALSE)),0),IFERROR(IF(I4="Hauswirtschaft",VLOOKUP($B4,[1]Kundenübersicht!$E$4:$BA$1003,MATCH("HW ab 2026 [€/Stunde]",[1]Kundenübersicht!$E$3:$BA$3,FALSE),FALSE),VLOOKUP($B4,[1]Kundenübersicht!$E$4:$BA$1003,MATCH("Alltagsbegleitung [€/Stunde]",[1]Kundenübersicht!$E$3:$BA$3,FALSE),FALSE)),0)) -> 32.75 | V4: =U4*F4 -> 65.5 | W4: =IF(AND(YEAR(C4)<=2025,X4="Alt"),0,G4*0.35) -> 0 | X4: =VLOOKUP(B4,[1]Kundenübersicht!E:AG,MATCH($X$3,[1]Kundenübersicht!$E$3:$AY$3,0),FALSE) -> Alt | Z4: Ja | AA4: 45959 | AC4: 45981 | AE4: =YEAR(C4) -> 2025 | AF4: =IF(MONTH(C4)<=9,"0"&MONTH(C4)&"."&YEAR(C4),MONTH(C4)&"."&YEAR(C4)) -> 05.2025 | AG4: =IF(H4="","",H4) -> Celina Panther | AH4: =IFERROR(VLOOKUP(B4,[1]Kundenübersicht!$E$4:$F$85,2,FALSE),"") -> Rosemarie Schröder | AI4: =IF(I4="","",I4) -> Hauswirtschaft | AJ4: =IF(J4="","",J4) -> Entlastungsleistung | AL4: =IF(I4="Hauswirtschaft",38,42) -> 38 | AM4: =AL4*F4 -> 76 | AN4: =G4*0.35 -> 0
B5: 00001|Rosemarie|Schröder | C5: 45804 | D5: 0.41666667 | E5: 0.5 | F5: =(E5-D5)*24 -> 2 | H5: Celina Panther | I5: Hauswirtschaft | J5: Entlastungsleistung | K5: =VLOOKUP($B5,[1]Kundenübersicht!$E$4:$AC$1003,MATCH(K$3,[1]Kundenübersicht!$E$3:$BA$3,FALSE),FALSE) -> Barmer Pflegekasse | L5: =VLOOKUP(B5,[1]Kundenübersicht!$E$4:$AC$1003,MATCH(L$3,[1]Kundenübersicht!$E$3:$BA$3,FALSE),FALSE) -> 184940005 | M5: =VLOOKUP(B5,[1]Kundenübersicht!$E$4:$AC$1003,MATCH(M$3,[1]Kundenübersicht!$E$3:$BA$3,FALSE),FALSE) -> Z817157321 | N5: =VLOOKUP(B5,[1]Kundenübersicht!$E$4:$AC$1003,MATCH(N$3,[1]Kundenübersicht!$E$3:$BA$3,FALSE),FALSE) -> PG 1 | P5: Ja | R5: Unterschrieben | S5: Link | U5: =IF(YEAR(C5)<=2025,IFERROR(IF(I5="Hauswirtschaft",VLOOKUP($B5,[1]Kundenübersicht!$E$4:$BA$1003,MATCH("Hauswirtschaft [€/Stunde]",[1]Kundenübersicht!$E$3:$BA$3,FALSE),FALSE),VLOOKUP($B5,[1]Kundenübersicht!$E$4:$BA$1003,MATCH("Alltagsbegleitung [€/Stunde]",[1]Kundenübersicht!$E$3:$BA$3,FALSE),FALSE)),0),IFERROR(IF(I5="Hauswirtschaft",VLOOKUP($B5,[1]Kundenübersicht!$E$4:$BA$1003,MATCH("HW ab 2026 [€/Stunde]",[1]Kundenübersicht!$E$3:$BA$3,FALSE),FALSE),VLOOKUP($B5,[1]Kundenübersicht!$E$4:$BA$1003,MATCH("Alltagsbegleitung [€/Stunde]",[1]Kundenübersicht!$E$3:$BA$3,FALSE),FALSE)),0)) -> 32.75 | V5: =U5*F5 -> 65.5 | W5: =IF(AND(YEAR(C5)<=2025,X5="Alt"),0,G5*0.35) -> 0 | X5: =VLOOKUP(B5,[1]Kundenübersicht!E:AG,MATCH($X$3,[1]Kundenübersicht!$E$3:$AY$3,0),FALSE) -> Alt | Z5: Ja | AA5: 45959 | AC5: 45981 | AE5: =YEAR(C5) -> 2025 | AF5: =IF(MONTH(C5)<=9,"0"&MONTH(C5)&"."&YEAR(C5),MONTH(C5)&"."&YEAR(C5)) -> 05.2025 | AG5: =IF(H5="","",H5) -> Celina Panther | AH5: =IFERROR(VLOOKUP(B5,[1]Kundenübersicht!$E$4:$F$85,2,FALSE),"") -> Rosemarie Schröder | AI5: =IF(I5="","",I5) -> Hauswirtschaft | AJ5: =IF(J5="","",J5) -> Entlastungsleistung | AL5: =IF(I5="Hauswirtschaft",38,42) -> 38 | AM5: =AL5*F5 -> 76 | AN5: =G5*0.35 -> 0
B6: 00002|Wolfgang|Nagler | C6: 45813 | D6: 0.41666667 | E6: 0.54166667 | F6: =(E6-D6)*24 -> 3 | H6: Christiane Fiebag | I6: Hauswirtschaft | J6: Entlastungsleistung | K6: =VLOOKUP($B6,[1]Kundenübersicht!$E$4:$AC$1003,MATCH(K$3,[1]Kundenübersicht!$E$3:$BA$3,FALSE),FALSE) -> IKK Classic | L6: =VLOOKUP(B6,[1]Kundenübersicht!$E$4:$AC$1003,MATCH(L$3,[1]Kundenübersicht!$E$3:$BA$3,FALSE),FALSE) -> 187202793 | M6: =VLOOKUP(B6,[1]Kundenübersicht!$E$4:$AC$1003,MATCH(M$3,[1]Kundenübersicht!$E$3:$BA$3,FALSE),FALSE) -> A268233642 | N6: =VLOOKUP(B6,[1]Kundenübersicht!$E$4:$AC$1003,MATCH(N$3,[1]Kundenübersicht!$E$3:$BA$3,FALSE),FALSE) -> PG 2 | P6: Ja | R6: Unterschrieben | S6: Link | U6: =IF(YEAR(C6)<=2025,IFERROR(IF(I6="Hauswirtschaft",VLOOKUP($B6,[1]Kundenübersicht!$E$4:$BA$1003,MATCH("Hauswirtschaft [€/Stunde]",[1]Kundenübersicht!$E$3:$BA$3,FALSE),FALSE),VLOOKUP($B6,[1]Kundenübersicht!$E$4:$BA$1003,MATCH("Alltagsbegleitung [€/Stunde]",[1]Kundenübersicht!$E$3:$BA$3,FALSE),FALSE)),0),IFERROR(IF(I6="Hauswirtschaft",VLOOKUP($B6,[1]Kundenübersicht!$E$4:$BA$1003,MATCH("HW ab 2026 [€/Stunde]",[1]Kundenübersicht!$E$3:$BA$3,FALSE),FALSE),VLOOKUP($B6,[1]Kundenübersicht!$E$4:$BA$1003,MATCH("Alltagsbegleitung [€/Stunde]",[1]Kundenübersicht!$E$3:$BA$3,FALSE),FALSE)),0)) -> 32.75 | V6: =U6*F6 -> 98.25 | W6: =IF(AND(YEAR(C6)<=2025,X6="Alt"),0,G6*0.35) -> 0 | X6: =VLOOKUP(B6,[1]Kundenübersicht!E:AG,MATCH($X$3,[1]Kundenübersicht!$E$3:$AY$3,0),FALSE) -> Alt | Z6: Ja | AA6: 45979 | AC6: 45995 | AE6: =YEAR(C6) -> 2025 | AF6: =IF(MONTH(C6)<=9,"0"&MONTH(C6)&"."&YEAR(C6),MONTH(C6)&"."&YEAR(C6)) -> 06.2025 | AG6: =IF(H6="","",H6) -> Christiane Fiebag | AH6: =IFERROR(VLOOKUP(B6,[1]Kundenübersicht!$E$4:$F$85,2,FALSE),"") -> Wolfgang Nagler | AI6: =IF(I6="","",I6) -> Hauswirtschaft | AJ6: =IF(J6="","",J6) -> Entlastungsleistung | AL6: =IF(I6="Hauswirtschaft",38,42) -> 38 | AM6: =AL6*F6 -> 114 | AN6: =G6*0.35 -> 0
B7: 00001|Rosemarie|Schröder | C7: 45814 | D7: 0.41666667 | E7: 0.5 | F7: =(E7-D7)*24 -> 2 | H7: Celina Panther | I7: Hauswirtschaft | J7: Entlastungsleistung | K7: =VLOOKUP($B7,[1]Kundenübersicht!$E$4:$AC$1003,MATCH(K$3,[1]Kundenübersicht!$E$3:$BA$3,FALSE),FALSE) -> Barmer Pflegekasse | L7: =VLOOKUP(B7,[1]Kundenübersicht!$E$4:$AC$1003,MATCH(L$3,[1]Kundenübersicht!$E$3:$BA$3,FALSE),FALSE) -> 184940005 | M7: =VLOOKUP(B7,[1]Kundenübersicht!$E$4:$AC$1003,MATCH(M$3,[1]Kundenübersicht!$E$3:$BA$3,FALSE),FALSE) -> Z817157321 | N7: =VLOOKUP(B7,[1]Kundenübersicht!$E$4:$AC$1003,MATCH(N$3,[1]Kundenübersicht!$E$3:$BA$3,FALSE),FALSE) -> PG 1 | P7: Ja | R7: Unterschrieben | S7: Link | U7: =IF(YEAR(C7)<=2025,IFERROR(IF(I7="Hauswirtschaft",VLOOKUP($B7,[1]Kundenübersicht!$E$4:$BA$1003,MATCH("Hauswirtschaft [€/Stunde]",[1]Kundenübersicht!$E$3:$BA$3,FALSE),FALSE),VLOOKUP($B7,[1]Kundenübersicht!$E$4:$BA$1003,MATCH("Alltagsbegleitung [€/Stunde]",[1]Kundenübersicht!$E$3:$BA$3,FALSE),FALSE)),0),IFERROR(IF(I7="Hauswirtschaft",VLOOKUP($B7,[1]Kundenübersicht!$E$4:$BA$1003,MATCH("HW ab 2026 [€/Stunde]",[1]Kundenübersicht!$E$3:$BA$3,FALSE),FALSE),VLOOKUP($B7,[1]Kundenübersicht!$E$4:$BA$1003,MATCH("Alltagsbegleitung [€/Stunde]",[1]Kundenübersicht!$E$3:$BA$3,FALSE),FALSE)),0)) -> 32.75 | V7: =U7*F7 -> 65.5 | W7: =IF(AND(YEAR(C7)<=2025,X7="Alt"),0,G7*0.35) -> 0 | X7: =VLOOKUP(B7,[1]Kundenübersicht!E:AG,MATCH($X$3,[1]Kundenübersicht!$E$3:$AY$3,0),FALSE) -> Alt | Z7: Ja | AA7: 45959 | AC7: 45981 | AE7: =YEAR(C7) -> 2025 | AF7: =IF(MONTH(C7)<=9,"0"&MONTH(C7)&"."&YEAR(C7),MONTH(C7)&"."&YEAR(C7)) -> 06.2025 | AG7: =IF(H7="","",H7) -> Celina Panther | AH7: =IFERROR(VLOOKUP(B7,[1]Kundenübersicht!$E$4:$F$85,2,FALSE),"") -> Rosemarie Schröder | AI7: =IF(I7="","",I7) -> Hauswirtschaft | AJ7: =IF(J7="","",J7) -> Entlastungsleistung | AL7: =IF(I7="Hauswirtschaft",38,42) -> 38 | AM7: =AL7*F7 -> 76 | AN7: =G7*0.35 -> 0
B8: 00006|Dieter|Berghold | C8: 45818 | D8: 0.45833333 | E8: 0.5 | F8: =(E8-D8)*24 -> 1 | H8: Christiane Fiebag | I8: Hauswirtschaft | J8: Entlastungsleistung | K8: =VLOOKUP($B8,[1]Kundenübersicht!$E$4:$AC$1003,MATCH(K$3,[1]Kundenübersicht!$E$3:$BA$3,FALSE),FALSE) -> AOK PLUS | L8: =VLOOKUP(B8,[1]Kundenübersicht!$E$4:$AC$1003,MATCH(L$3,[1]Kundenübersicht!$E$3:$BA$3,FALSE),FALSE) -> 107299005 | M8: =VLOOKUP(B8,[1]Kundenübersicht!$E$4:$AC$1003,MATCH(M$3,[1]Kundenübersicht!$E$3:$BA$3,FALSE),FALSE) -> R234942678 | N8: =VLOOKUP(B8,[1]Kundenübersicht!$E$4:$AC$1003,MATCH(N$3,[1]Kundenübersicht!$E$3:$BA$3,FALSE),FALSE) -> PG 2 | P8: Ja | R8: Unterschrieben | S8: Link | U8: =IF(YEAR(C8)<=2025,IFERROR(IF(I8="Hauswirtschaft",VLOOKUP($B8,[1]Kundenübersicht!$E$4:$BA$1003,MATCH("Hauswirtschaft [€/Stunde]",[1]Kundenübersicht!$E$3:$BA$3,FALSE),FALSE),VLOOKUP($B8,[1]Kundenübersicht!$E$4:$BA$1003,MATCH("Alltagsbegleitung [€/Stunde]",[1]Kundenübersicht!$E$3:$BA$3,FALSE),FALSE)),0),IFERROR(IF(I8="Hauswirtschaft",VLOOKUP($B8,[1]Kundenübersicht!$E$4:$BA$1003,MATCH("HW ab 2026 [€/Stunde]",[1]Kundenübersicht!$E$3:$BA$3,FALSE),FALSE),VLOOKUP($B8,[1]Kundenübersicht!$E$4:$BA$1003,MATCH("Alltagsbegleitung [€/Stunde]",[1]Kundenübersicht!$E$3:$BA$3,FALSE),FALSE)),0)) -> 32.75 | V8: =U8*F8 -> 32.75 | W8: =IF(AND(YEAR(C8)<=2025,X8="Alt"),0,G8*0.35) -> 0 | X8: =VLOOKUP(B8,[1]Kundenübersicht!E:AG,MATCH($X$3,[1]Kundenübersicht!$E$3:$AY$3,0),FALSE) -> Alt | Z8: Ja | AC8: 45917 | AE8: =YEAR(C8) -> 2025 | AF8: =IF(MONTH(C8)<=9,"0"&MONTH(C8)&"."&YEAR(C8),MONTH(C8)&"."&YEAR(C8)) -> 06.2025 | AG8: =IF(H8="","",H8) -> Christiane Fiebag | AH8: =IFERROR(VLOOKUP(B8,[1]Kundenübersicht!$E$4:$F$85,2,FALSE),"") -> Dieter Berghold | AI8: =IF(I8="","",I8) -> Hauswirtschaft | AJ8: =IF(J8="","",J8) -> Entlastungsleistung | AL8: =IF(I8="Hauswirtschaft",38,42) -> 38 | AM8: =AL8*F8 -> 38 | AN8: =G8*0.35 -> 0
B9: 00007|Elke|Berghold | C9: 45818 | D9: 0.5 | E9: 0.54166667 | F9: =(E9-D9)*24 -> 1 | H9: Christiane Fiebag | I9: Hauswirtschaft | J9: Entlastungsleistung | K9: =VLOOKUP($B9,[1]Kundenübersicht!$E$4:$AC$1003,MATCH(K$3,[1]Kundenübersicht!$E$3:$BA$3,FALSE),FALSE) -> AOK PLUS | L9: =VLOOKUP(B9,[1]Kundenübersicht!$E$4:$AC$1003,MATCH(L$3,[1]Kundenübersicht!$E$3:$BA$3,FALSE),FALSE) -> 107299005 | M9: =VLOOKUP(B9,[1]Kundenübersicht!$E$4:$AC$1003,MATCH(M$3,[1]Kundenübersicht!$E$3:$BA$3,FALSE),FALSE) -> P722909118 | N9: =VLOOKUP(B9,[1]Kundenübersicht!$E$4:$AC$1003,MATCH(N$3,[1]Kundenübersicht!$E$3:$BA$3,FALSE),FALSE) -> PG 3 | P9: Ja | R9: Unterschrieben | S9: Link | U9: =IF(YEAR(C9)<=2025,IFERROR(IF(I9="Hauswirtschaft",VLOOKUP($B9,[1]Kundenübersicht!$E$4:$BA$1003,MATCH("Hauswirtschaft [€/Stunde]",[1]Kundenübersicht!$E$3:$BA$3,FALSE),FALSE),VLOOKUP($B9,[1]Kundenübersicht!$E$4:$BA$1003,MATCH("Alltagsbegleitung [€/Stunde]",[1]Kundenübersicht!$E$3:$BA$3,FALSE),FALSE)),0),IFERROR(IF(I9="Hauswirtschaft",VLOOKUP($B9,[1]Kundenübersicht!$E$4:$BA$1003,MATCH("HW ab 2026 [€/Stunde]",[1]Kundenübersicht!$E$3:$BA$3,FALSE),FALSE),VLOOKUP($B9,[1]Kundenübersicht!$E$4:$BA$1003,MATCH("Alltagsbegleitung [€/Stunde]",[1]Kundenübersicht!$E$3:$BA$3,FALSE),FALSE)),0)) -> 32.75 | V9: =U9*F9 -> 32.75 | W9: =IF(AND(YEAR(C9)<=2025,X9="Alt"),0,G9*0.35) -> 0 | X9: =VLOOKUP(B9,[1]Kundenübersicht!E:AG,MATCH($X$3,[1]Kundenübersicht!$E$3:$AY$3,0),FALSE) -> Alt | Z9: Ja | AC9: 45917 | AE9: =YEAR(C9) -> 2025 | AF9: =IF(MONTH(C9)<=9,"0"&MONTH(C9)&"."&YEAR(C9),MONTH(C9)&"."&YEAR(C9)) -> 06.2025 | AG9: =IF(H9="","",H9) -> Christiane Fiebag | AH9: =IFERROR(VLOOKUP(B9,[1]Kundenübersicht!$E$4:$F$85,2,FALSE),"") -> Elke Berghold | AI9: =IF(I9="","",I9) -> Hauswirtschaft | AJ9: =IF(J9="","",J9) -> Entlastungsleistung | AL9: =IF(I9="Hauswirtschaft",38,42) -> 38 | AM9: =AL9*F9 -> 38 | AN9: =G9*0.35 -> 0
B10: 00004|Ingrid|Haufe | C10: 45821 | D10: 0.41666667 | E10: 0.5 | F10: =(E10-D10)*24 -> 2 | H10: Celina Panther | I10: Hauswirtschaft | J10: Entlastungsleistung | K10: =VLOOKUP($B10,[1]Kundenübersicht!$E$4:$AC$1003,MATCH(K$3,[1]Kundenübersicht!$E$3:$BA$3,FALSE),FALSE) -> IKK Classic | L10: =VLOOKUP(B10,[1]Kundenübersicht!$E$4:$AC$1003,MATCH(L$3,[1]Kundenübersicht!$E$3:$BA$3,FALSE),FALSE) -> 187202793 | M10: =VLOOKUP(B10,[1]Kundenübersicht!$E$4:$AC$1003,MATCH(M$3,[1]Kundenübersicht!$E$3:$BA$3,FALSE),FALSE) -> X365499146 | N10: =VLOOKUP(B10,[1]Kundenübersicht!$E$4:$AC$1003,MATCH(N$3,[1]Kundenübersicht!$E$3:$BA$3,FALSE),FALSE) -> PG 1 | P10: Ja | R10: Unterschrieben | S10: Link | U10: =IF(YEAR(C10)<=2025,IFERROR(IF(I10="Hauswirtschaft",VLOOKUP($B10,[1]Kundenübersicht!$E$4:$BA$1003,MATCH("Hauswirtschaft [€/Stunde]",[1]Kundenübersicht!$E$3:$BA$3,FALSE),FALSE),VLOOKUP($B10,[1]Kundenübersicht!$E$4:$BA$1003,MATCH("Alltagsbegleitung [€/Stunde]",[1]Kundenübersicht!$E$3:$BA$3,FALSE),FALSE)),0),IFERROR(IF(I10="Hauswirtschaft",VLOOKUP($B10,[1]Kundenübersicht!$E$4:$BA$1003,MATCH("HW ab 2026 [€/Stunde]",[1]Kundenübersicht!$E$3:$BA$3,FALSE),FALSE),VLOOKUP($B10,[1]Kundenübersicht!$E$4:$BA$1003,MATCH("Alltagsbegleitung [€/Stunde]",[1]Kundenübersicht!$E$3:$BA$3,FALSE),FALSE)),0)) -> 32.75 | V10: =U10*F10 -> 65.5 | W10: =IF(AND(YEAR(C10)<=2025,X10="Alt"),0,G10*0.35) -> 0 | X10: =VLOOKUP(B10,[1]Kundenübersicht!E:AG,MATCH($X$3,[1]Kundenübersicht!$E$3:$AY$3,0),FALSE) -> Alt | Z10: Ja | AA10: 45979 | AC10: 45995 | AE10: =YEAR(C10) -> 2025 | AF10: =IF(MONTH(C10)<=9,"0"&MONTH(C10)&"."&YEAR(C10),MONTH(C10)&"."&YEAR(C10)) -> 06.2025 | AG10: =IF(H10="","",H10) -> Celina Panther | AH10: =IFERROR(VLOOKUP(B10,[1]Kundenübersicht!$E$4:$F$85,2,FALSE),"") -> Ingrid Haufe | AI10: =IF(I10="","",I10) -> Hauswirtschaft | AJ10: =IF(J10="","",J10) -> Entlastungsleistung | AL10: =IF(I10="Hauswirtschaft",38,42) -> 38 | AM10: =AL10*F10 -> 76 | AN10: =G10*0.35 -> 0
B11: 00005|Lothar|Haufe | C11: 45821 | D11: 0.41666667 | E11: 0.5 | F11: =(E11-D11)*24 -> 2 | H11: Celina Panther | I11: Hauswirtschaft | J11: Entlastungsleistung | K11: =VLOOKUP($B11,[1]Kundenübersicht!$E$4:$AC$1003,MATCH(K$3,[1]Kundenübersicht!$E$3:$BA$3,FALSE),FALSE) -> IKK Classic | L11: =VLOOKUP(B11,[1]Kundenübersicht!$E$4:$AC$1003,MATCH(L$3,[1]Kundenübersicht!$E$3:$BA$3,FALSE),FALSE) -> 187202793 | M11: =VLOOKUP(B11,[1]Kundenübersicht!$E$4:$AC$1003,MATCH(M$3,[1]Kundenübersicht!$E$3:$BA$3,FALSE),FALSE) -> E434900220 | N11: =VLOOKUP(B11,[1]Kundenübersicht!$E$4:$AC$1003,MATCH(N$3,[1]Kundenübersicht!$E$3:$BA$3,FALSE),FALSE) -> PG 1 | P11: Ja | R11: Unterschrieben | S11: Link | U11: =IF(YEAR(C11)<=2025,IFERROR(IF(I11="Hauswirtschaft",VLOOKUP($B11,[1]Kundenübersicht!$E$4:$BA$1003,MATCH("Hauswirtschaft [€/Stunde]",[1]Kundenübersicht!$E$3:$BA$3,FALSE),FALSE),VLOOKUP($B11,[1]Kundenübersicht!$E$4:$BA$1003,MATCH("Alltagsbegleitung [€/Stunde]",[1]Kundenübersicht!$E$3:$BA$3,FALSE),FALSE)),0),IFERROR(IF(I11="Hauswirtschaft",VLOOKUP($B11,[1]Kundenübersicht!$E$4:$BA$1003,MATCH("HW ab 2026 [€/Stunde]",[1]Kundenübersicht!$E$3:$BA$3,FALSE),FALSE),VLOOKUP($B11,[1]Kundenübersicht!$E$4:$BA$1003,MATCH("Alltagsbegleitung [€/Stunde]",[1]Kundenübersicht!$E$3:$BA$3,FALSE),FALSE)),0)) -> 32.75 | V11: =U11*F11 -> 65.5 | W11: =IF(AND(YEAR(C11)<=2025,X11="Alt"),0,G11*0.35) -> 0 | X11: =VLOOKUP(B11,[1]Kundenübersicht!E:AG,MATCH($X$3,[1]Kundenübersicht!$E$3:$AY$3,0),FALSE) -> Alt | Z11: Ja | AA11: 45979 | AC11: 45995 | AE11: =YEAR(C11) -> 2025 | AF11: =IF(MONTH(C11)<=9,"0"&MONTH(C11)&"."&YEAR(C11),MONTH(C11)&"."&YEAR(C11)) -> 06.2025 | AG11: =IF(H11="","",H11) -> Celina Panther | AH11: =IFERROR(VLOOKUP(B11,[1]Kundenübersicht!$E$4:$F$85,2,FALSE),"") -> Lothar Haufe | AI11: =IF(I11="","",I11) -> Hauswirtschaft | AJ11: =IF(J11="","",J11) -> Entlastungsleistung | AL11: =IF(I11="Hauswirtschaft",38,42) -> 38 | AM11: =AL11*F11 -> 76 | AN11: =G11*0.35 -> 0
B12: 00007|Elke|Berghold | C12: 45824 | D12: 0.45833333 | E12: 0.5 | F12: =(E12-D12)*24 -> 1 | H12: Christiane Fiebag | I12: Hauswirtschaft | J12: Entlastungsleistung | K12: =VLOOKUP($B12,[1]Kundenübersicht!$E$4:$AC$1003,MATCH(K$3,[1]Kundenübersicht!$E$3:$BA$3,FALSE),FALSE) -> AOK PLUS | L12: =VLOOKUP(B12,[1]Kundenübersicht!$E$4:$AC$1003,MATCH(L$3,[1]Kundenübersicht!$E$3:$BA$3,FALSE),FALSE) -> 107299005 | M12: =VLOOKUP(B12,[1]Kundenübersicht!$E$4:$AC$1003,MATCH(M$3,[1]Kundenübersicht!$E$3:$BA$3,FALSE),FALSE) -> P722909118 | N12: =VLOOKUP(B12,[1]Kundenübersicht!$E$4:$AC$1003,MATCH(N$3,[1]Kundenübersicht!$E$3:$BA$3,FALSE),FALSE) -> PG 3 | P12: Ja | R12: Unterschrieben | S12: Link | U12: =IF(YEAR(C12)<=2025,IFERROR(IF(I12="Hauswirtschaft",VLOOKUP($B12,[1]Kundenübersicht!$E$4:$BA$1003,MATCH("Hauswirtschaft [€/Stunde]",[1]Kundenübersicht!$E$3:$BA$3,FALSE),FALSE),VLOOKUP($B12,[1]Kundenübersicht!$E$4:$BA$1003,MATCH("Alltagsbegleitung [€/Stunde]",[1]Kundenübersicht!$E$3:$BA$3,FALSE),FALSE)),0),IFERROR(IF(I12="Hauswirtschaft",VLOOKUP($B12,[1]Kundenübersicht!$E$4:$BA$1003,MATCH("HW ab 2026 [€/Stunde]",[1]Kundenübersicht!$E$3:$BA$3,FALSE),FALSE),VLOOKUP($B12,[1]Kundenübersicht!$E$4:$BA$1003,MATCH("Alltagsbegleitung [€/Stunde]",[1]Kundenübersicht!$E$3:$BA$3,FALSE),FALSE)),0)) -> 32.75 | V12: =U12*F12 -> 32.75 | W12: =IF(AND(YEAR(C12)<=2025,X12="Alt"),0,G12*0.35) -> 0 | X12: =VLOOKUP(B12,[1]Kundenübersicht!E:AG,MATCH($X$3,[1]Kundenübersicht!$E$3:$AY$3,0),FALSE) -> Alt | Z12: Ja | AC12: 45917 | AE12: =YEAR(C12) -> 2025 | AF12: =IF(MONTH(C12)<=9,"0"&MONTH(C12)&"."&YEAR(C12),MONTH(C12)&"."&YEAR(C12)) -> 06.2025 | AG12: =IF(H12="","",H12) -> Christiane Fiebag | AH12: =IFERROR(VLOOKUP(B12,[1]Kundenübersicht!$E$4:$F$85,2,FALSE),"") -> Elke Berghold | AI12: =IF(I12="","",I12) -> Hauswirtschaft | AJ12: =IF(J12="","",J12) -> Entlastungsleistung | AL12: =IF(I12="Hauswirtschaft",38,42) -> 38 | AM12: =AL12*F12 -> 38 | AN12: =G12*0.35 -> 0
B13: 00006|Dieter|Berghold | C13: 45824 | D13: 0.5 | E13: 0.54166667 | F13: =(E13-D13)*24 -> 1 | H13: Christiane Fiebag | I13: Hauswirtschaft | J13: Entlastungsleistung | K13: =VLOOKUP($B13,[1]Kundenübersicht!$E$4:$AC$1003,MATCH(K$3,[1]Kundenübersicht!$E$3:$BA$3,FALSE),FALSE) -> AOK PLUS | L13: =VLOOKUP(B13,[1]Kundenübersicht!$E$4:$AC$1003,MATCH(L$3,[1]Kundenübersicht!$E$3:$BA$3,FALSE),FALSE) -> 107299005 | M13: =VLOOKUP(B13,[1]Kundenübersicht!$E$4:$AC$1003,MATCH(M$3,[1]Kundenübersicht!$E$3:$BA$3,FALSE),FALSE) -> R234942678 | N13: =VLOOKUP(B13,[1]Kundenübersicht!$E$4:$AC$1003,MATCH(N$3,[1]Kundenübersicht!$E$3:$BA$3,FALSE),FALSE) -> PG 2 | P13: Ja | R13: Unterschrieben | S13: Link | U13: =IF(YEAR(C13)<=2025,IFERROR(IF(I13="Hauswirtschaft",VLOOKUP($B13,[1]Kundenübersicht!$E$4:$BA$1003,MATCH("Hauswirtschaft [€/Stunde]",[1]Kundenübersicht!$E$3:$BA$3,FALSE),FALSE),VLOOKUP($B13,[1]Kundenübersicht!$E$4:$BA$1003,MATCH("Alltagsbegleitung [€/Stunde]",[1]Kundenübersicht!$E$3:$BA$3,FALSE),FALSE)),0),IFERROR(IF(I13="Hauswirtschaft",VLOOKUP($B13,[1]Kundenübersicht!$E$4:$BA$1003,MATCH("HW ab 2026 [€/Stunde]",[1]Kundenübersicht!$E$3:$BA$3,FALSE),FALSE),VLOOKUP($B13,[1]Kundenübersicht!$E$4:$BA$1003,MATCH("Alltagsbegleitung [€/Stunde]",[1]Kundenübersicht!$E$3:$BA$3,FALSE),FALSE)),0)) -> 32.75 | V13: =U13*F13 -> 32.75 | W13: =IF(AND(YEAR(C13)<=2025,X13="Alt"),0,G13*0.35) -> 0 | X13: =VLOOKUP(B13,[1]Kundenübersicht!E:AG,MATCH($X$3,[1]Kundenübersicht!$E$3:$AY$3,0),FALSE) -> Alt | Z13: Ja | AC13: 45917 | AE13: =YEAR(C13) -> 2025 | AF13: =IF(MONTH(C13)<=9,"0"&MONTH(C13)&"."&YEAR(C13),MONTH(C13)&"."&YEAR(C13)) -> 06.2025 | AG13: =IF(H13="","",H13) -> Christiane Fiebag | AH13: =IFERROR(VLOOKUP(B13,[1]Kundenübersicht!$E$4:$F$85,2,FALSE),"") -> Dieter Berghold | AI13: =IF(I13="","",I13) -> Hauswirtschaft | AJ13: =IF(J13="","",J13) -> Entlastungsleistung | AL13: =IF(I13="Hauswirtschaft",38,42) -> 38 | AM13: =AL13*F13 -> 38 | AN13: =G13*0.35 -> 0
B14: 00001|Rosemarie|Schröder | C14: 45824 | D14: 0.41666667 | E14: 0.5 | F14: =(E14-D14)*24 -> 2 | H14: Celina Panther | I14: Hauswirtschaft | J14: Entlastungsleistung | K14: =VLOOKUP($B14,[1]Kundenübersicht!$E$4:$AC$1003,MATCH(K$3,[1]Kundenübersicht!$E$3:$BA$3,FALSE),FALSE) -> Barmer Pflegekasse | L14: =VLOOKUP(B14,[1]Kundenübersicht!$E$4:$AC$1003,MATCH(L$3,[1]Kundenübersicht!$E$3:$BA$3,FALSE),FALSE) -> 184940005 | M14: =VLOOKUP(B14,[1]Kundenübersicht!$E$4:$AC$1003,MATCH(M$3,[1]Kundenübersicht!$E$3:$BA$3,FALSE),FALSE) -> Z817157321 | N14: =VLOOKUP(B14,[1]Kundenübersicht!$E$4:$AC$1003,MATCH(N$3,[1]Kundenübersicht!$E$3:$BA$3,FALSE),FALSE) -> PG 1 | P14: Ja | R14: Unterschrieben | S14: Link | U14: =IF(YEAR(C14)<=2025,IFERROR(IF(I14="Hauswirtschaft",VLOOKUP($B14,[1]Kundenübersicht!$E$4:$BA$1003,MATCH("Hauswirtschaft [€/Stunde]",[1]Kundenübersicht!$E$3:$BA$3,FALSE),FALSE),VLOOKUP($B14,[1]Kundenübersicht!$E$4:$BA$1003,MATCH("Alltagsbegleitung [€/Stunde]",[1]Kundenübersicht!$E$3:$BA$3,FALSE),FALSE)),0),IFERROR(IF(I14="Hauswirtschaft",VLOOKUP($B14,[1]Kundenübersicht!$E$4:$BA$1003,MATCH("HW ab 2026 [€/Stunde]",[1]Kundenübersicht!$E$3:$BA$3,FALSE),FALSE),VLOOKUP($B14,[1]Kundenübersicht!$E$4:$BA$1003,MATCH("Alltagsbegleitung [€/Stunde]",[1]Kundenübersicht!$E$3:$BA$3,FALSE),FALSE)),0)) -> 32.75 | V14: =U14*F14 -> 65.5 | W14: =IF(AND(YEAR(C14)<=2025,X14="Alt"),0,G14*0.35) -> 0 | X14: =VLOOKUP(B14,[1]Kundenübersicht!E:AG,MATCH($X$3,[1]Kundenübersicht!$E$3:$AY$3,0),FALSE) -> Alt | Z14: Ja | AA14: 45959 | AC14: 45981 | AE14: =YEAR(C14) -> 2025 | AF14: =IF(MONTH(C14)<=9,"0"&MONTH(C14)&"."&YEAR(C14),MONTH(C14)&"."&YEAR(C14)) -> 06.2025 | AG14: =IF(H14="","",H14) -> Celina Panther | AH14: =IFERROR(VLOOKUP(B14,[1]Kundenübersicht!$E$4:$F$85,2,FALSE),"") -> Rosemarie Schröder | AI14: =IF(I14="","",I14) -> Hauswirtschaft | AJ14: =IF(J14="","",J14) -> Entlastungsleistung | AL14: =IF(I14="Hauswirtschaft",38,42) -> 38 | AM14: =AL14*F14 -> 76 | AN14: =G14*0.35 -> 0
B15: 00008|Christian|Jungnickel | C15: 45828 | D15: 0.33333333 | E15: 0.41666667 | F15: =(E15-D15)*24 -> 2 | H15: Christiane Fiebag | I15: Hauswirtschaft | J15: Entlastungsleistung | K15: =VLOOKUP($B15,[1]Kundenübersicht!$E$4:$AC$1003,MATCH(K$3,[1]Kundenübersicht!$E$3:$BA$3,FALSE),FALSE) -> AOK PLUS | L15: =VLOOKUP(B15,[1]Kundenübersicht!$E$4:$AC$1003,MATCH(L$3,[1]Kundenübersicht!$E$3:$BA$3,FALSE),FALSE) -> 107299005 | M15: =VLOOKUP(B15,[1]Kundenübersicht!$E$4:$AC$1003,MATCH(M$3,[1]Kundenübersicht!$E$3:$BA$3,FALSE),FALSE) -> R782602114 | N15: =VLOOKUP(B15,[1]Kundenübersicht!$E$4:$AC$1003,MATCH(N$3,[1]Kundenübersicht!$E$3:$BA$3,FALSE),FALSE) -> PG 1 | P15: Ja | R15: Unterschrieben | S15: Link | U15: =IF(YEAR(C15)<=2025,IFERROR(IF(I15="Hauswirtschaft",VLOOKUP($B15,[1]Kundenübersicht!$E$4:$BA$1003,MATCH("Hauswirtschaft [€/Stunde]",[1]Kundenübersicht!$E$3:$BA$3,FALSE),FALSE),VLOOKUP($B15,[1]Kundenübersicht!$E$4:$BA$1003,MATCH("Alltagsbegleitung [€/Stunde]",[1]Kundenübersicht!$E$3:$BA$3,FALSE),FALSE)),0),IFERROR(IF(I15="Hauswirtschaft",VLOOKUP($B15,[1]Kundenübersicht!$E$4:$BA$1003,MATCH("HW ab 2026 [€/Stunde]",[1]Kundenübersicht!$E$3:$BA$3,FALSE),FALSE),VLOOKUP($B15,[1]Kundenübersicht!$E$4:$BA$1003,MATCH("Alltagsbegleitung [€/Stunde]",[1]Kundenübersicht!$E$3:$BA$3,FALSE),FALSE)),0)) -> 32.75 | V15: =U15*F15 -> 65.5 | W15: =IF(AND(YEAR(C15)<=2025,X15="Alt"),0,G15*0.35) -> 0 | X15: =VLOOKUP(B15,[1]Kundenübersicht!E:AG,MATCH($X$3,[1]Kundenübersicht!$E$3:$AY$3,0),FALSE) -> Alt | Z15: Ja | AC15: 45917 | AE15: =YEAR(C15) -> 2025 | AF15: =IF(MONTH(C15)<=9,"0"&MONTH(C15)&"."&YEAR(C15),MONTH(C15)&"."&YEAR(C15)) -> 06.2025 | AG15: =IF(H15="","",H15) -> Christiane Fiebag | AH15: =IFERROR(VLOOKUP(B15,[1]Kundenübersicht!$E$4:$F$85,2,FALSE),"") -> Christian Jungnickel | AI15: =IF(I15="","",I15) -> Hauswirtschaft | AJ15: =IF(J15="","",J15) -> Entlastungsleistung | AL15: =IF(I15="Hauswirtschaft",38,42) -> 38 | AM15: =AL15*F15 -> 76 | AN15: =G15*0.35 -> 0
B16: 00004|Ingrid|Haufe | C16: 45828 | D16: 0.41666667 | E16: 0.5 | F16: =(E16-D16)*24 -> 2 | H16: Celina Panther | I16: Hauswirtschaft | J16: Entlastungsleistung | K16: =VLOOKUP($B16,[1]Kundenübersicht!$E$4:$AC$1003,MATCH(K$3,[1]Kundenübersicht!$E$3:$BA$3,FALSE),FALSE) -> IKK Classic | L16: =VLOOKUP(B16,[1]Kundenübersicht!$E$4:$AC$1003,MATCH(L$3,[1]Kundenübersicht!$E$3:$BA$3,FALSE),FALSE) -> 187202793 | M16: =VLOOKUP(B16,[1]Kundenübersicht!$E$4:$AC$1003,MATCH(M$3,[1]Kundenübersicht!$E$3:$BA$3,FALSE),FALSE) -> X365499146 | N16: =VLOOKUP(B16,[1]Kundenübersicht!$E$4:$AC$1003,MATCH(N$3,[1]Kundenübersicht!$E$3:$BA$3,FALSE),FALSE) -> PG 1 | P16: Ja | R16: Unterschrieben | S16: Link | U16: =IF(YEAR(C16)<=2025,IFERROR(IF(I16="Hauswirtschaft",VLOOKUP($B16,[1]Kundenübersicht!$E$4:$BA$1003,MATCH("Hauswirtschaft [€/Stunde]",[1]Kundenübersicht!$E$3:$BA$3,FALSE),FALSE),VLOOKUP($B16,[1]Kundenübersicht!$E$4:$BA$1003,MATCH("Alltagsbegleitung [€/Stunde]",[1]Kundenübersicht!$E$3:$BA$3,FALSE),FALSE)),0),IFERROR(IF(I16="Hauswirtschaft",VLOOKUP($B16,[1]Kundenübersicht!$E$4:$BA$1003,MATCH("HW ab 2026 [€/Stunde]",[1]Kundenübersicht!$E$3:$BA$3,FALSE),FALSE),VLOOKUP($B16,[1]Kundenübersicht!$E$4:$BA$1003,MATCH("Alltagsbegleitung [€/Stunde]",[1]Kundenübersicht!$E$3:$BA$3,FALSE),FALSE)),0)) -> 32.75 | V16: =U16*F16 -> 65.5 | W16: =IF(AND(YEAR(C16)<=2025,X16="Alt"),0,G16*0.35) -> 0 | X16: =VLOOKUP(B16,[1]Kundenübersicht!E:AG,MATCH($X$3,[1]Kundenübersicht!$E$3:$AY$3,0),FALSE) -> Alt | Z16: Ja | AA16: 45979 | AC16: 45995 | AE16: =YEAR(C16) -> 2025 | AF16: =IF(MONTH(C16)<=9,"0"&MONTH(C16)&"."&YEAR(C16),MONTH(C16)&"."&YEAR(C16)) -> 06.2025 | AG16: =IF(H16="","",H16) -> Celina Panther | AH16: =IFERROR(VLOOKUP(B16,[1]Kundenübersicht!$E$4:$F$85,2,FALSE),"") -> Ingrid Haufe | AI16: =IF(I16="","",I16) -> Hauswirtschaft | AJ16: =IF(J16="","",J16) -> Entlastungsleistung | AL16: =IF(I16="Hauswirtschaft",38,42) -> 38 | AM16: =AL16*F16 -> 76 | AN16: =G16*0.35 -> 0
B17: 00005|Lothar|Haufe | C17: 45828 | D17: 0.41666667 | E17: 0.5 | F17: =(E17-D17)*24 -> 2 | H17: Celina Panther | I17: Hauswirtschaft | J17: Entlastungsleistung | K17: =VLOOKUP($B17,[1]Kundenübersicht!$E$4:$AC$1003,MATCH(K$3,[1]Kundenübersicht!$E$3:$BA$3,FALSE),FALSE) -> IKK Classic | L17: =VLOOKUP(B17,[1]Kundenübersicht!$E$4:$AC$1003,MATCH(L$3,[1]Kundenübersicht!$E$3:$BA$3,FALSE),FALSE) -> 187202793 | M17: =VLOOKUP(B17,[1]Kundenübersicht!$E$4:$AC$1003,MATCH(M$3,[1]Kundenübersicht!$E$3:$BA$3,FALSE),FALSE) -> E434900220 | N17: =VLOOKUP(B17,[1]Kundenübersicht!$E$4:$AC$1003,MATCH(N$3,[1]Kundenübersicht!$E$3:$BA$3,FALSE),FALSE) -> PG 1 | P17: Ja | R17: Unterschrieben | S17: Link | U17: =IF(YEAR(C17)<=2025,IFERROR(IF(I17="Hauswirtschaft",VLOOKUP($B17,[1]Kundenübersicht!$E$4:$BA$1003,MATCH("Hauswirtschaft [€/Stunde]",[1]Kundenübersicht!$E$3:$BA$3,FALSE),FALSE),VLOOKUP($B17,[1]Kundenübersicht!$E$4:$BA$1003,MATCH("Alltagsbegleitung [€/Stunde]",[1]Kundenübersicht!$E$3:$BA$3,FALSE),FALSE)),0),IFERROR(IF(I17="Hauswirtschaft",VLOOKUP($B17,[1]Kundenübersicht!$E$4:$BA$1003,MATCH("HW ab 2026 [€/Stunde]",[1]Kundenübersicht!$E$3:$BA$3,FALSE),FALSE),VLOOKUP($B17,[1]Kundenübersicht!$E$4:$BA$1003,MATCH("Alltagsbegleitung [€/Stunde]",[1]Kundenübersicht!$E$3:$BA$3,FALSE),FALSE)),0)) -> 32.75 | V17: =U17*F17 -> 65.5 | W17: =IF(AND(YEAR(C17)<=2025,X17="Alt"),0,G17*0.35) -> 0 | X17: =VLOOKUP(B17,[1]Kundenübersicht!E:AG,MATCH($X$3,[1]Kundenübersicht!$E$3:$AY$3,0),FALSE) -> Alt | Z17: Ja | AA17: 45979 | AC17: 45995 | AE17: =YEAR(C17) -> 2025 | AF17: =IF(MONTH(C17)<=9,"0"&MONTH(C17)&"."&YEAR(C17),MONTH(C17)&"."&YEAR(C17)) -> 06.2025 | AG17: =IF(H17="","",H17) -> Celina Panther | AH17: =IFERROR(VLOOKUP(B17,[1]Kundenübersicht!$E$4:$F$85,2,FALSE),"") -> Lothar Haufe | AI17: =IF(I17="","",I17) -> Hauswirtschaft | AJ17: =IF(J17="","",J17) -> Entlastungsleistung | AL17: =IF(I17="Hauswirtschaft",38,42) -> 38 | AM17: =AL17*F17 -> 76 | AN17: =G17*0.35 -> 0
B18: 00006|Dieter|Berghold | C18: 45831 | D18: 0.54166667 | E18: 0.58333333 | F18: =(E18-D18)*24 -> 1 | H18: Christiane Fiebag | I18: Hauswirtschaft | J18: Entlastungsleistung | K18: =VLOOKUP($B18,[1]Kundenübersicht!$E$4:$AC$1003,MATCH(K$3,[1]Kundenübersicht!$E$3:$BA$3,FALSE),FALSE) -> AOK PLUS | L18: =VLOOKUP(B18,[1]Kundenübersicht!$E$4:$AC$1003,MATCH(L$3,[1]Kundenübersicht!$E$3:$BA$3,FALSE),FALSE) -> 107299005 | M18: =VLOOKUP(B18,[1]Kundenübersicht!$E$4:$AC$1003,MATCH(M$3,[1]Kundenübersicht!$E$3:$BA$3,FALSE),FALSE) -> R234942678 | N18: =VLOOKUP(B18,[1]Kundenübersicht!$E$4:$AC$1003,MATCH(N$3,[1]Kundenübersicht!$E$3:$BA$3,FALSE),FALSE) -> PG 2 | P18: Ja | R18: Unterschrieben | S18: Link | U18: =IF(YEAR(C18)<=2025,IFERROR(IF(I18="Hauswirtschaft",VLOOKUP($B18,[1]Kundenübersicht!$E$4:$BA$1003,MATCH("Hauswirtschaft [€/Stunde]",[1]Kundenübersicht!$E$3:$BA$3,FALSE),FALSE),VLOOKUP($B18,[1]Kundenübersicht!$E$4:$BA$1003,MATCH("Alltagsbegleitung [€/Stunde]",[1]Kundenübersicht!$E$3:$BA$3,FALSE),FALSE)),0),IFERROR(IF(I18="Hauswirtschaft",VLOOKUP($B18,[1]Kundenübersicht!$E$4:$BA$1003,MATCH("HW ab 2026 [€/Stunde]",[1]Kundenübersicht!$E$3:$BA$3,FALSE),FALSE),VLOOKUP($B18,[1]Kundenübersicht!$E$4:$BA$1003,MATCH("Alltagsbegleitung [€/Stunde]",[1]Kundenübersicht!$E$3:$BA$3,FALSE),FALSE)),0)) -> 32.75 | V18: =U18*F18 -> 32.75 | W18: =IF(AND(YEAR(C18)<=2025,X18="Alt"),0,G18*0.35) -> 0 | X18: =VLOOKUP(B18,[1]Kundenübersicht!E:AG,MATCH($X$3,[1]Kundenübersicht!$E$3:$AY$3,0),FALSE) -> Alt | Z18: Ja | AC18: 45917 | AE18: =YEAR(C18) -> 2025 | AF18: =IF(MONTH(C18)<=9,"0"&MONTH(C18)&"."&YEAR(C18),MONTH(C18)&"."&YEAR(C18)) -> 06.2025 | AG18: =IF(H18="","",H18) -> Christiane Fiebag | AH18: =IFERROR(VLOOKUP(B18,[1]Kundenübersicht!$E$4:$F$85,2,FALSE),"") -> Dieter Berghold | AI18: =IF(I18="","",I18) -> Hauswirtschaft | AJ18: =IF(J18="","",J18) -> Entlastungsleistung | AL18: =IF(I18="Hauswirtschaft",38,42) -> 38 | AM18: =AL18*F18 -> 38 | AN18: =G18*0.35 -> 0
B19: 00007|Elke|Berghold | C19: 45831 | D19: 0.5 | E19: 0.54166667 | F19: =(E19-D19)*24 -> 1 | H19: Christiane Fiebag | I19: Hauswirtschaft | J19: Entlastungsleistung | K19: =VLOOKUP($B19,[1]Kundenübersicht!$E$4:$AC$1003,MATCH(K$3,[1]Kundenübersicht!$E$3:$BA$3,FALSE),FALSE) -> AOK PLUS | L19: =VLOOKUP(B19,[1]Kundenübersicht!$E$4:$AC$1003,MATCH(L$3,[1]Kundenübersicht!$E$3:$BA$3,FALSE),FALSE) -> 107299005 | M19: =VLOOKUP(B19,[1]Kundenübersicht!$E$4:$AC$1003,MATCH(M$3,[1]Kundenübersicht!$E$3:$BA$3,FALSE),FALSE) -> P722909118 | N19: =VLOOKUP(B19,[1]Kundenübersicht!$E$4:$AC$1003,MATCH(N$3,[1]Kundenübersicht!$E$3:$BA$3,FALSE),FALSE) -> PG 3 | P19: Ja | R19: Unterschrieben | S19: Link | U19: =IF(YEAR(C19)<=2025,IFERROR(IF(I19="Hauswirtschaft",VLOOKUP($B19,[1]Kundenübersicht!$E$4:$BA$1003,MATCH("Hauswirtschaft [€/Stunde]",[1]Kundenübersicht!$E$3:$BA$3,FALSE),FALSE),VLOOKUP($B19,[1]Kundenübersicht!$E$4:$BA$1003,MATCH("Alltagsbegleitung [€/Stunde]",[1]Kundenübersicht!$E$3:$BA$3,FALSE),FALSE)),0),IFERROR(IF(I19="Hauswirtschaft",VLOOKUP($B19,[1]Kundenübersicht!$E$4:$BA$1003,MATCH("HW ab 2026 [€/Stunde]",[1]Kundenübersicht!$E$3:$BA$3,FALSE),FALSE),VLOOKUP($B19,[1]Kundenübersicht!$E$4:$BA$1003,MATCH("Alltagsbegleitung [€/Stunde]",[1]Kundenübersicht!$E$3:$BA$3,FALSE),FALSE)),0)) -> 32.75 | V19: =U19*F19 -> 32.75 | W19: =IF(AND(YEAR(C19)<=2025,X19="Alt"),0,G19*0.35) -> 0 | X19: =VLOOKUP(B19,[1]Kundenübersicht!E:AG,MATCH($X$3,[1]Kundenübersicht!$E$3:$AY$3,0),FALSE) -> Alt | Z19: Ja | AC19: 45917 | AE19: =YEAR(C19) -> 2025 | AF19: =IF(MONTH(C19)<=9,"0"&MONTH(C19)&"."&YEAR(C19),MONTH(C19)&"."&YEAR(C19)) -> 06.2025 | AG19: =IF(H19="","",H19) -> Christiane Fiebag | AH19: =IFERROR(VLOOKUP(B19,[1]Kundenübersicht!$E$4:$F$85,2,FALSE),"") -> Elke Berghold | AI19: =IF(I19="","",I19) -> Hauswirtschaft | AJ19: =IF(J19="","",J19) -> Entlastungsleistung | AL19: =IF(I19="Hauswirtschaft",38,42) -> 38 | AM19: =AL19*F19 -> 38 | AN19: =G19*0.35 -> 0
B20: 00010|Helga|Dienelt | C20: 45833 | D20: 0.63541667 | E20: 0.67708333 | F20: =(E20-D20)*24 -> 1 | H20: Franziska Wächtler | I20: Alltagsbegleitung | J20: Entlastungsleistung | K20: =VLOOKUP($B20,[1]Kundenübersicht!$E$4:$AC$1003,MATCH(K$3,[1]Kundenübersicht!$E$3:$BA$3,FALSE),FALSE) -> AOK PLUS | L20: =VLOOKUP(B20,[1]Kundenübersicht!$E$4:$AC$1003,MATCH(L$3,[1]Kundenübersicht!$E$3:$BA$3,FALSE),FALSE) -> 107299005 | M20: =VLOOKUP(B20,[1]Kundenübersicht!$E$4:$AC$1003,MATCH(M$3,[1]Kundenübersicht!$E$3:$BA$3,FALSE),FALSE) -> Q445657677 | N20: =VLOOKUP(B20,[1]Kundenübersicht!$E$4:$AC$1003,MATCH(N$3,[1]Kundenübersicht!$E$3:$BA$3,FALSE),FALSE) -> PG 2 | P20: Ja | R20: Unterschrieben | S20: Link | U20: =IF(YEAR(C20)<=2025,IFERROR(IF(I20="Hauswirtschaft",VLOOKUP($B20,[1]Kundenübersicht!$E$4:$BA$1003,MATCH("Hauswirtschaft [€/Stunde]",[1]Kundenübersicht!$E$3:$BA$3,FALSE),FALSE),VLOOKUP($B20,[1]Kundenübersicht!$E$4:$BA$1003,MATCH("Alltagsbegleitung [€/Stunde]",[1]Kundenübersicht!$E$3:$BA$3,FALSE),FALSE)),0),IFERROR(IF(I20="Hauswirtschaft",VLOOKUP($B20,[1]Kundenübersicht!$E$4:$BA$1003,MATCH("HW ab 2026 [€/Stunde]",[1]Kundenübersicht!$E$3:$BA$3,FALSE),FALSE),VLOOKUP($B20,[1]Kundenübersicht!$E$4:$BA$1003,MATCH("Alltagsbegleitung [€/Stunde]",[1]Kundenübersicht!$E$3:$BA$3,FALSE),FALSE)),0)) -> 42 | V20: =U20*F20 -> 42 | W20: =IF(AND(YEAR(C20)<=2025,X20="Alt"),0,G20*0.35) -> 0 | X20: =VLOOKUP(B20,[1]Kundenübersicht!E:AG,MATCH($X$3,[1]Kundenübersicht!$E$3:$AY$3,0),FALSE) -> Alt | Z20: Ja | AC20: 45917 | AE20: =YEAR(C20) -> 2025 | AF20: =IF(MONTH(C20)<=9,"0"&MONTH(C20)&"."&YEAR(C20),MONTH(C20)&"."&YEAR(C20)) -> 06.2025 | AG20: =IF(H20="","",H20) -> Franziska Wächtler | AH20: =IFERROR(VLOOKUP(B20,[1]Kundenübersicht!$E$4:$F$85,2,FALSE),"") -> Helga Dienelt | AI20: =IF(I20="","",I20) -> Alltagsbegleitung | AJ20: =IF(J20="","",J20) -> Entlastungsleistung | AL20: =IF(I20="Hauswirtschaft",38,42) -> 42 | AM20: =AL20*F20 -> 42 | AN20: =G20*0.35 -> 0
B21: 00011|Martin|Schmidt | C21: 45838 | D21: 0.59375 | E21: 0.63541667 | F21: =(E21-D21)*24 -> 1 | H21: Christiane Fiebag | I21: Hauswirtschaft | J21: Entlastungsleistung | K21: =VLOOKUP($B21,[1]Kundenübersicht!$E$4:$AC$1003,MATCH(K$3,[1]Kundenübersicht!$E$3:$BA$3,FALSE),FALSE) -> Techniker Krankenkasse | L21: =VLOOKUP(B21,[1]Kundenübersicht!$E$4:$AC$1003,MATCH(L$3,[1]Kundenübersicht!$E$3:$BA$3,FALSE),FALSE) -> 101575519 | M21: =VLOOKUP(B21,[1]Kundenübersicht!$E$4:$AC$1003,MATCH(M$3,[1]Kundenübersicht!$E$3:$BA$3,FALSE),FALSE) -> E759973784 | N21: =VLOOKUP(B21,[1]Kundenübersicht!$E$4:$AC$1003,MATCH(N$3,[1]Kundenübersicht!$E$3:$BA$3,FALSE),FALSE) -> PG 2 | P21: Ja | R21: Unterschrieben | S21: Link | U21: =IF(YEAR(C21)<=2025,IFERROR(IF(I21="Hauswirtschaft",VLOOKUP($B21,[1]Kundenübersicht!$E$4:$BA$1003,MATCH("Hauswirtschaft [€/Stunde]",[1]Kundenübersicht!$E$3:$BA$3,FALSE),FALSE),VLOOKUP($B21,[1]Kundenübersicht!$E$4:$BA$1003,MATCH("Alltagsbegleitung [€/Stunde]",[1]Kundenübersicht!$E$3:$BA$3,FALSE),FALSE)),0),IFERROR(IF(I21="Hauswirtschaft",VLOOKUP($B21,[1]Kundenübersicht!$E$4:$BA$1003,MATCH("HW ab 2026 [€/Stunde]",[1]Kundenübersicht!$E$3:$BA$3,FALSE),FALSE),VLOOKUP($B21,[1]Kundenübersicht!$E$4:$BA$1003,MATCH("Alltagsbegleitung [€/Stunde]",[1]Kundenübersicht!$E$3:$BA$3,FALSE),FALSE)),0)) -> 32.75 | V21: =U21*F21 -> 32.75 | W21: =IF(AND(YEAR(C21)<=2025,X21="Alt"),0,G21*0.35) -> 0 | X21: =VLOOKUP(B21,[1]Kundenübersicht!E:AG,MATCH($X$3,[1]Kundenübersicht!$E$3:$AY$3,0),FALSE) -> Alt | Z21: Ja | AA21: 45950 | AC21: 45972 | AE21: =YEAR(C21) -> 2025 | AF21: =IF(MONTH(C21)<=9,"0"&MONTH(C21)&"."&YEAR(C21),MONTH(C21)&"."&YEAR(C21)) -> 06.2025 | AG21: =IF(H21="","",H21) -> Christiane Fiebag | AH21: =IFERROR(VLOOKUP(B21,[1]Kundenübersicht!$E$4:$F$85,2,FALSE),"") -> Martin Schmidt | AI21: =IF(I21="","",I21) -> Hauswirtschaft | AJ21: =IF(J21="","",J21) -> Entlastungsleistung | AL21: =IF(I21="Hauswirtschaft",38,42) -> 38 | AM21: =AL21*F21 -> 38 | AN21: =G21*0.35 -> 0
B22: 00010|Helga|Dienelt | C22: 45840 | D22: 0.63541667 | E22: 0.67708333 | F22: =(E22-D22)*24 -> 1 | H22: Franziska Wächtler | I22: Alltagsbegleitung | J22: Entlastungsleistung | K22: =VLOOKUP($B22,[1]Kundenübersicht!$E$4:$AC$1003,MATCH(K$3,[1]Kundenübersicht!$E$3:$BA$3,FALSE),FALSE) -> AOK PLUS | L22: =VLOOKUP(B22,[1]Kundenübersicht!$E$4:$AC$1003,MATCH(L$3,[1]Kundenübersicht!$E$3:$BA$3,FALSE),FALSE) -> 107299005 | M22: =VLOOKUP(B22,[1]Kundenübersicht!$E$4:$AC$1003,MATCH(M$3,[1]Kundenübersicht!$E$3:$BA$3,FALSE),FALSE) -> Q445657677 | N22: =VLOOKUP(B22,[1]Kundenübersicht!$E$4:$AC$1003,MATCH(N$3,[1]Kundenübersicht!$E$3:$BA$3,FALSE),FALSE) -> PG 2 | P22: Ja | R22: Unterschrieben | S22: Link | U22: =IF(YEAR(C22)<=2025,IFERROR(IF(I22="Hauswirtschaft",VLOOKUP($B22,[1]Kundenübersicht!$E$4:$BA$1003,MATCH("Hauswirtschaft [€/Stunde]",[1]Kundenübersicht!$E$3:$BA$3,FALSE),FALSE),VLOOKUP($B22,[1]Kundenübersicht!$E$4:$BA$1003,MATCH("Alltagsbegleitung [€/Stunde]",[1]Kundenübersicht!$E$3:$BA$3,FALSE),FALSE)),0),IFERROR(IF(I22="Hauswirtschaft",VLOOKUP($B22,[1]Kundenübersicht!$E$4:$BA$1003,MATCH("HW ab 2026 [€/Stunde]",[1]Kundenübersicht!$E$3:$BA$3,FALSE),FALSE),VLOOKUP($B22,[1]Kundenübersicht!$E$4:$BA$1003,MATCH("Alltagsbegleitung [€/Stunde]",[1]Kundenübersicht!$E$3:$BA$3,FALSE),FALSE)),0)) -> 42 | V22: =U22*F22 -> 42 | W22: =IF(AND(YEAR(C22)<=2025,X22="Alt"),0,G22*0.35) -> 0 | X22: =VLOOKUP(B22,[1]Kundenübersicht!E:AG,MATCH($X$3,[1]Kundenübersicht!$E$3:$AY$3,0),FALSE) -> Alt | Z22: Ja | AC22: 45917 | AE22: =YEAR(C22) -> 2025 | AF22: =IF(MONTH(C22)<=9,"0"&MONTH(C22)&"."&YEAR(C22),MONTH(C22)&"."&YEAR(C22)) -> 07.2025 | AG22: =IF(H22="","",H22) -> Franziska Wächtler | AH22: =IFERROR(VLOOKUP(B22,[1]Kundenübersicht!$E$4:$F$85,2,FALSE),"") -> Helga Dienelt | AI22: =IF(I22="","",I22) -> Alltagsbegleitung | AJ22: =IF(J22="","",J22) -> Entlastungsleistung | AL22: =IF(I22="Hauswirtschaft",38,42) -> 42 | AM22: =AL22*F22 -> 42 | AN22: =G22*0.35 -> 0
B23: 00006|Dieter|Berghold | C23: 45842 | D23: 0.45833333 | E23: 0.5 | F23: =(E23-D23)*24 -> 1 | H23: Christiane Fiebag | I23: Hauswirtschaft | J23: Entlastungsleistung | K23: =VLOOKUP($B23,[1]Kundenübersicht!$E$4:$AC$1003,MATCH(K$3,[1]Kundenübersicht!$E$3:$BA$3,FALSE),FALSE) -> AOK PLUS | L23: =VLOOKUP(B23,[1]Kundenübersicht!$E$4:$AC$1003,MATCH(L$3,[1]Kundenübersicht!$E$3:$BA$3,FALSE),FALSE) -> 107299005 | M23: =VLOOKUP(B23,[1]Kundenübersicht!$E$4:$AC$1003,MATCH(M$3,[1]Kundenübersicht!$E$3:$BA$3,FALSE),FALSE) -> R234942678 | N23: =VLOOKUP(B23,[1]Kundenübersicht!$E$4:$AC$1003,MATCH(N$3,[1]Kundenübersicht!$E$3:$BA$3,FALSE),FALSE) -> PG 2 | P23: Ja | R23: Unterschrieben | S23: Link | U23: =IF(YEAR(C23)<=2025,IFERROR(IF(I23="Hauswirtschaft",VLOOKUP($B23,[1]Kundenübersicht!$E$4:$BA$1003,MATCH("Hauswirtschaft [€/Stunde]",[1]Kundenübersicht!$E$3:$BA$3,FALSE),FALSE),VLOOKUP($B23,[1]Kundenübersicht!$E$4:$BA$1003,MATCH("Alltagsbegleitung [€/Stunde]",[1]Kundenübersicht!$E$3:$BA$3,FALSE),FALSE)),0),IFERROR(IF(I23="Hauswirtschaft",VLOOKUP($B23,[1]Kundenübersicht!$E$4:$BA$1003,MATCH("HW ab 2026 [€/Stunde]",[1]Kundenübersicht!$E$3:$BA$3,FALSE),FALSE),VLOOKUP($B23,[1]Kundenübersicht!$E$4:$BA$1003,MATCH("Alltagsbegleitung [€/Stunde]",[1]Kundenübersicht!$E$3:$BA$3,FALSE),FALSE)),0)) -> 32.75 | V23: =U23*F23 -> 32.75 | W23: =IF(AND(YEAR(C23)<=2025,X23="Alt"),0,G23*0.35) -> 0 | X23: =VLOOKUP(B23,[1]Kundenübersicht!E:AG,MATCH($X$3,[1]Kundenübersicht!$E$3:$AY$3,0),FALSE) -> Alt | Z23: Ja | AA23: 45950 | AC23: 45975 | AE23: =YEAR(C23) -> 2025 | AF23: =IF(MONTH(C23)<=9,"0"&MONTH(C23)&"."&YEAR(C23),MONTH(C23)&"."&YEAR(C23)) -> 07.2025 | AG23: =IF(H23="","",H23) -> Christiane Fiebag | AH23: =IFERROR(VLOOKUP(B23,[1]Kundenübersicht!$E$4:$F$85,2,FALSE),"") -> Dieter Berghold | AI23: =IF(I23="","",I23) -> Hauswirtschaft | AJ23: =IF(J23="","",J23) -> Entlastungsleistung | AL23: =IF(I23="Hauswirtschaft",38,42) -> 38 | AM23: =AL23*F23 -> 38 | AN23: =G23*0.35 -> 0
B24: 00007|Elke|Berghold | C24: 45842 | D24: 0.5 | E24: 0.54166667 | F24: =(E24-D24)*24 -> 1 | H24: Christiane Fiebag | I24: Hauswirtschaft | J24: Entlastungsleistung | K24: =VLOOKUP($B24,[1]Kundenübersicht!$E$4:$AC$1003,MATCH(K$3,[1]Kundenübersicht!$E$3:$BA$3,FALSE),FALSE) -> AOK PLUS | L24: =VLOOKUP(B24,[1]Kundenübersicht!$E$4:$AC$1003,MATCH(L$3,[1]Kundenübersicht!$E$3:$BA$3,FALSE),FALSE) -> 107299005 | M24: =VLOOKUP(B24,[1]Kundenübersicht!$E$4:$AC$1003,MATCH(M$3,[1]Kundenübersicht!$E$3:$BA$3,FALSE),FALSE) -> P722909118 | N24: =VLOOKUP(B24,[1]Kundenübersicht!$E$4:$AC$1003,MATCH(N$3,[1]Kundenübersicht!$E$3:$BA$3,FALSE),FALSE) -> PG 3 | P24: Ja | R24: Unterschrieben | S24: Link | U24: =IF(YEAR(C24)<=2025,IFERROR(IF(I24="Hauswirtschaft",VLOOKUP($B24,[1]Kundenübersicht!$E$4:$BA$1003,MATCH("Hauswirtschaft [€/Stunde]",[1]Kundenübersicht!$E$3:$BA$3,FALSE),FALSE),VLOOKUP($B24,[1]Kundenübersicht!$E$4:$BA$1003,MATCH("Alltagsbegleitung [€/Stunde]",[1]Kundenübersicht!$E$3:$BA$3,FALSE),FALSE)),0),IFERROR(IF(I24="Hauswirtschaft",VLOOKUP($B24,[1]Kundenübersicht!$E$4:$BA$1003,MATCH("HW ab 2026 [€/Stunde]",[1]Kundenübersicht!$E$3:$BA$3,FALSE),FALSE),VLOOKUP($B24,[1]Kundenübersicht!$E$4:$BA$1003,MATCH("Alltagsbegleitung [€/Stunde]",[1]Kundenübersicht!$E$3:$BA$3,FALSE),FALSE)),0)) -> 32.75 | V24: =U24*F24 -> 32.75 | W24: =IF(AND(YEAR(C24)<=2025,X24="Alt"),0,G24*0.35) -> 0 | X24: =VLOOKUP(B24,[1]Kundenübersicht!E:AG,MATCH($X$3,[1]Kundenübersicht!$E$3:$AY$3,0),FALSE) -> Alt | Z24: Ja | AA24: 45950 | AC24: 45975 | AE24: =YEAR(C24) -> 2025 | AF24: =IF(MONTH(C24)<=9,"0"&MONTH(C24)&"."&YEAR(C24),MONTH(C24)&"."&YEAR(C24)) -> 07.2025 | AG24: =IF(H24="","",H24) -> Christiane Fiebag | AH24: =IFERROR(VLOOKUP(B24,[1]Kundenübersicht!$E$4:$F$85,2,FALSE),"") -> Elke Berghold | AI24: =IF(I24="","",I24) -> Hauswirtschaft | AJ24: =IF(J24="","",J24) -> Entlastungsleistung | AL24: =IF(I24="Hauswirtschaft",38,42) -> 38 | AM24: =AL24*F24 -> 38 | AN24: =G24*0.35 -> 0
B25: 00014|Inge|Leupold | C25: 45845 | D25: 0.46875 | E25: 0.51041667 | F25: =(E25-D25)*24 -> 1 | H25: Christiane Fiebag | I25: Hauswirtschaft | J25: Entlastungsleistung | K25: =VLOOKUP($B25,[1]Kundenübersicht!$E$4:$AC$1003,MATCH(K$3,[1]Kundenübersicht!$E$3:$BA$3,FALSE),FALSE) -> AOK PLUS | L25: =VLOOKUP(B25,[1]Kundenübersicht!$E$4:$AC$1003,MATCH(L$3,[1]Kundenübersicht!$E$3:$BA$3,FALSE),FALSE) -> 107299005 | M25: =VLOOKUP(B25,[1]Kundenübersicht!$E$4:$AC$1003,MATCH(M$3,[1]Kundenübersicht!$E$3:$BA$3,FALSE),FALSE) -> I323820679 | N25: =VLOOKUP(B25,[1]Kundenübersicht!$E$4:$AC$1003,MATCH(N$3,[1]Kundenübersicht!$E$3:$BA$3,FALSE),FALSE) -> PG 1 | P25: Ja | R25: Unterschrieben | S25: Link | U25: =IF(YEAR(C25)<=2025,IFERROR(IF(I25="Hauswirtschaft",VLOOKUP($B25,[1]Kundenübersicht!$E$4:$BA$1003,MATCH("Hauswirtschaft [€/Stunde]",[1]Kundenübersicht!$E$3:$BA$3,FALSE),FALSE),VLOOKUP($B25,[1]Kundenübersicht!$E$4:$BA$1003,MATCH("Alltagsbegleitung [€/Stunde]",[1]Kundenübersicht!$E$3:$BA$3,FALSE),FALSE)),0),IFERROR(IF(I25="Hauswirtschaft",VLOOKUP($B25,[1]Kundenübersicht!$E$4:$BA$1003,MATCH("HW ab 2026 [€/Stunde]",[1]Kundenübersicht!$E$3:$BA$3,FALSE),FALSE),VLOOKUP($B25,[1]Kundenübersicht!$E$4:$BA$1003,MATCH("Alltagsbegleitung [€/Stunde]",[1]Kundenübersicht!$E$3:$BA$3,FALSE),FALSE)),0)) -> 32.75 | V25: =U25*F25 -> 32.75 | W25: =IF(AND(YEAR(C25)<=2025,X25="Alt"),0,G25*0.35) -> 0 | X25: =VLOOKUP(B25,[1]Kundenübersicht!E:AG,MATCH($X$3,[1]Kundenübersicht!$E$3:$AY$3,0),FALSE) -> Alt | Z25: Ja | AC25: 45917 | AE25: =YEAR(C25) -> 2025 | AF25: =IF(MONTH(C25)<=9,"0"&MONTH(C25)&"."&YEAR(C25),MONTH(C25)&"."&YEAR(C25)) -> 07.2025 | AG25: =IF(H25="","",H25) -> Christiane Fiebag | AH25: =IFERROR(VLOOKUP(B25,[1]Kundenübersicht!$E$4:$F$85,2,FALSE),"") -> Inge Leupold | AI25: =IF(I25="","",I25) -> Hauswirtschaft | AJ25: =IF(J25="","",J25) -> Entlastungsleistung | AL25: =IF(I25="Hauswirtschaft",38,42) -> 38 | AM25: =AL25*F25 -> 38 | AN25: =G25*0.35 -> 0
B26: 00009|Dieter|Kraft | C26: 45845 | D26: 0.53125 | E26: 0.63541667 | F26: =(E26-D26)*24 -> 2.5 | H26: Christiane Fiebag | I26: Hauswirtschaft | J26: Entlastungsleistung | K26: =VLOOKUP($B26,[1]Kundenübersicht!$E$4:$AC$1003,MATCH(K$3,[1]Kundenübersicht!$E$3:$BA$3,FALSE),FALSE) -> Barmer Pflegekasse | L26: =VLOOKUP(B26,[1]Kundenübersicht!$E$4:$AC$1003,MATCH(L$3,[1]Kundenübersicht!$E$3:$BA$3,FALSE),FALSE) -> 184940005 | M26: =VLOOKUP(B26,[1]Kundenübersicht!$E$4:$AC$1003,MATCH(M$3,[1]Kundenübersicht!$E$3:$BA$3,FALSE),FALSE) -> Y800652371 | N26: =VLOOKUP(B26,[1]Kundenübersicht!$E$4:$AC$1003,MATCH(N$3,[1]Kundenübersicht!$E$3:$BA$3,FALSE),FALSE) -> PG 1 | P26: Ja | R26: Unterschrieben | S26: Link | U26: =IF(YEAR(C26)<=2025,IFERROR(IF(I26="Hauswirtschaft",VLOOKUP($B26,[1]Kundenübersicht!$E$4:$BA$1003,MATCH("Hauswirtschaft [€/Stunde]",[1]Kundenübersicht!$E$3:$BA$3,FALSE),FALSE),VLOOKUP($B26,[1]Kundenübersicht!$E$4:$BA$1003,MATCH("Alltagsbegleitung [€/Stunde]",[1]Kundenübersicht!$E$3:$BA$3,FALSE),FALSE)),0),IFERROR(IF(I26="Hauswirtschaft",VLOOKUP($B26,[1]Kundenübersicht!$E$4:$BA$1003,MATCH("HW ab 2026 [€/Stunde]",[1]Kundenübersicht!$E$3:$BA$3,FALSE),FALSE),VLOOKUP($B26,[1]Kundenübersicht!$E$4:$BA$1003,MATCH("Alltagsbegleitung [€/Stunde]",[1]Kundenübersicht!$E$3:$BA$3,FALSE),FALSE)),0)) -> 32.75 | V26: =U26*F26 -> 81.875 | W26: =IF(AND(YEAR(C26)<=2025,X26="Alt"),0,G26*0.35) -> 0 | X26: =VLOOKUP(B26,[1]Kundenübersicht!E:AG,MATCH($X$3,[1]Kundenübersicht!$E$3:$AY$3,0),FALSE) -> Alt | Z26: Ja | AE26: =YEAR(C26) -> 2025 | AF26: =IF(MONTH(C26)<=9,"0"&MONTH(C26)&"."&YEAR(C26),MONTH(C26)&"."&YEAR(C26)) -> 07.2025 | AG26: =IF(H26="","",H26) -> Christiane Fiebag | AH26: =IFERROR(VLOOKUP(B26,[1]Kundenübersicht!$E$4:$F$85,2,FALSE),"") -> Dieter Kraft | AI26: =IF(I26="","",I26) -> Hauswirtschaft | AJ26: =IF(J26="","",J26) -> Entlastungsleistung | AL26: =IF(I26="Hauswirtschaft",38,42) -> 38 | AM26: =AL26*F26 -> 95 | AN26: =G26*0.35 -> 0
B27: 00010|Helga|Dienelt | C27: 45846 | D27: 0.64583333 | E27: 0.6875 | F27: =(E27-D27)*24 -> 1 | H27: Franziska Wächtler | I27: Alltagsbegleitung | J27: Entlastungsleistung | K27: =VLOOKUP($B27,[1]Kundenübersicht!$E$4:$AC$1003,MATCH(K$3,[1]Kundenübersicht!$E$3:$BA$3,FALSE),FALSE) -> AOK PLUS | L27: =VLOOKUP(B27,[1]Kundenübersicht!$E$4:$AC$1003,MATCH(L$3,[1]Kundenübersicht!$E$3:$BA$3,FALSE),FALSE) -> 107299005 | M27: =VLOOKUP(B27,[1]Kundenübersicht!$E$4:$AC$1003,MATCH(M$3,[1]Kundenübersicht!$E$3:$BA$3,FALSE),FALSE) -> Q445657677 | N27: =VLOOKUP(B27,[1]Kundenübersicht!$E$4:$AC$1003,MATCH(N$3,[1]Kundenübersicht!$E$3:$BA$3,FALSE),FALSE) -> PG 2 | P27: Ja | R27: Unterschrieben | S27: Link | U27: =IF(YEAR(C27)<=2025,IFERROR(IF(I27="Hauswirtschaft",VLOOKUP($B27,[1]Kundenübersicht!$E$4:$BA$1003,MATCH("Hauswirtschaft [€/Stunde]",[1]Kundenübersicht!$E$3:$BA$3,FALSE),FALSE),VLOOKUP($B27,[1]Kundenübersicht!$E$4:$BA$1003,MATCH("Alltagsbegleitung [€/Stunde]",[1]Kundenübersicht!$E$3:$BA$3,FALSE),FALSE)),0),IFERROR(IF(I27="Hauswirtschaft",VLOOKUP($B27,[1]Kundenübersicht!$E$4:$BA$1003,MATCH("HW ab 2026 [€/Stunde]",[1]Kundenübersicht!$E$3:$BA$3,FALSE),FALSE),VLOOKUP($B27,[1]Kundenübersicht!$E$4:$BA$1003,MATCH("Alltagsbegleitung [€/Stunde]",[1]Kundenübersicht!$E$3:$BA$3,FALSE),FALSE)),0)) -> 42 | V27: =U27*F27 -> 42 | W27: =IF(AND(YEAR(C27)<=2025,X27="Alt"),0,G27*0.35) -> 0 | X27: =VLOOKUP(B27,[1]Kundenübersicht!E:AG,MATCH($X$3,[1]Kundenübersicht!$E$3:$AY$3,0),FALSE) -> Alt | Z27: Ja | AC27: 45917 | AE27: =YEAR(C27) -> 2025 | AF27: =IF(MONTH(C27)<=9,"0"&MONTH(C27)&"."&YEAR(C27),MONTH(C27)&"."&YEAR(C27)) -> 07.2025 | AG27: =IF(H27="","",H27) -> Franziska Wächtler | AH27: =IFERROR(VLOOKUP(B27,[1]Kundenübersicht!$E$4:$F$85,2,FALSE),"") -> Helga Dienelt | AI27: =IF(I27="","",I27) -> Alltagsbegleitung | AJ27: =IF(J27="","",J27) -> Entlastungsleistung | AL27: =IF(I27="Hauswirtschaft",38,42) -> 42 | AM27: =AL27*F27 -> 42 | AN27: =G27*0.35 -> 0
B28: 00015|Hella|Reißig | C28: 45848 | D28: 0.66666667 | E28: 0.70833333 | F28: =(E28-D28)*24 -> 1 | H28: Manuela Richter | I28: Hauswirtschaft | J28: Entlastungsleistung | K28: KNAPPSCHAFT | L28: 109990508 | M28: F862750970 | N28: =VLOOKUP(B28,[1]Kundenübersicht!$E$4:$AC$1003,MATCH(N$3,[1]Kundenübersicht!$E$3:$BA$3,FALSE),FALSE) -> PG 1 | P28: Ja | R28: Unterschrieben | S28: Link | U28: =IF(YEAR(C28)<=2025,IFERROR(IF(I28="Hauswirtschaft",VLOOKUP($B28,[1]Kundenübersicht!$E$4:$BA$1003,MATCH("Hauswirtschaft [€/Stunde]",[1]Kundenübersicht!$E$3:$BA$3,FALSE),FALSE),VLOOKUP($B28,[1]Kundenübersicht!$E$4:$BA$1003,MATCH("Alltagsbegleitung [€/Stunde]",[1]Kundenübersicht!$E$3:$BA$3,FALSE),FALSE)),0),IFERROR(IF(I28="Hauswirtschaft",VLOOKUP($B28,[1]Kundenübersicht!$E$4:$BA$1003,MATCH("HW ab 2026 [€/Stunde]",[1]Kundenübersicht!$E$3:$BA$3,FALSE),FALSE),VLOOKUP($B28,[1]Kundenübersicht!$E$4:$BA$1003,MATCH("Alltagsbegleitung [€/Stunde]",[1]Kundenübersicht!$E$3:$BA$3,FALSE),FALSE)),0)) -> 32.75 | V28: =U28*F28 -> 32.75 | W28: =IF(AND(YEAR(C28)<=2025,X28="Alt"),0,G28*0.35) -> 0 | X28: =VLOOKUP(B28,[1]Kundenübersicht!E:AG,MATCH($X$3,[1]Kundenübersicht!$E$3:$AY$3,0),FALSE) -> Alt | Z28: Ja | AC28: 45924 | AE28: =YEAR(C28) -> 2025 | AF28: =IF(MONTH(C28)<=9,"0"&MONTH(C28)&"."&YEAR(C28),MONTH(C28)&"."&YEAR(C28)) -> 07.2025 | AG28: =IF(H28="","",H28) -> Manuela Richter | AH28: =IFERROR(VLOOKUP(B28,[1]Kundenübersicht!$E$4:$F$85,2,FALSE),"") -> Hella Reißig | AI28: =IF(I28="","",I28) -> Hauswirtschaft | AJ28: =IF(J28="","",J28) -> Entlastungsleistung | AL28: =IF(I28="Hauswirtschaft",38,42) -> 38 | AM28: =AL28*F28 -> 38 | AN28: =G28*0.35 -> 0
B29: 00013|Rita|Neubert | C29: 45848 | D29: 0.60416667 | E29: 0.64583333 | F29: =(E29-D29)*24 -> 1 | H29: Manuela Richter | I29: Hauswirtschaft | J29: Entlastungsleistung | K29: =VLOOKUP($B29,[1]Kundenübersicht!$E$4:$AC$1003,MATCH(K$3,[1]Kundenübersicht!$E$3:$BA$3,FALSE),FALSE) -> AOK PLUS | L29: =VLOOKUP(B29,[1]Kundenübersicht!$E$4:$AC$1003,MATCH(L$3,[1]Kundenübersicht!$E$3:$BA$3,FALSE),FALSE) -> 107299005 | M29: =VLOOKUP(B29,[1]Kundenübersicht!$E$4:$AC$1003,MATCH(M$3,[1]Kundenübersicht!$E$3:$BA$3,FALSE),FALSE) -> T309560658 | N29: =VLOOKUP(B29,[1]Kundenübersicht!$E$4:$AC$1003,MATCH(N$3,[1]Kundenübersicht!$E$3:$BA$3,FALSE),FALSE) -> PG 2 | P29: Ja | R29: Unterschrieben | S29: Link | U29: =IF(YEAR(C29)<=2025,IFERROR(IF(I29="Hauswirtschaft",VLOOKUP($B29,[1]Kundenübersicht!$E$4:$BA$1003,MATCH("Hauswirtschaft [€/Stunde]",[1]Kundenübersicht!$E$3:$BA$3,FALSE),FALSE),VLOOKUP($B29,[1]Kundenübersicht!$E$4:$BA$1003,MATCH("Alltagsbegleitung [€/Stunde]",[1]Kundenübersicht!$E$3:$BA$3,FALSE),FALSE)),0),IFERROR(IF(I29="Hauswirtschaft",VLOOKUP($B29,[1]Kundenübersicht!$E$4:$BA$1003,MATCH("HW ab 2026 [€/Stunde]",[1]Kundenübersicht!$E$3:$BA$3,FALSE),FALSE),VLOOKUP($B29,[1]Kundenübersicht!$E$4:$BA$1003,MATCH("Alltagsbegleitung [€/Stunde]",[1]Kundenübersicht!$E$3:$BA$3,FALSE),FALSE)),0)) -> 32.75 | V29: =U29*F29 -> 32.75 | W29: =IF(AND(YEAR(C29)<=2025,X29="Alt"),0,G29*0.35) -> 0 | X29: =VLOOKUP(B29,[1]Kundenübersicht!E:AG,MATCH($X$3,[1]Kundenübersicht!$E$3:$AY$3,0),FALSE) -> Alt | Z29: Ja | AC29: 45917 | AE29: =YEAR(C29) -> 2025 | AF29: =IF(MONTH(C29)<=9,"0"&MONTH(C29)&"."&YEAR(C29),MONTH(C29)&"."&YEAR(C29)) -> 07.2025 | AG29: =IF(H29="","",H29) -> Manuela Richter | AH29: =IFERROR(VLOOKUP(B29,[1]Kundenübersicht!$E$4:$F$85,2,FALSE),"") -> Rita Neubert | AI29: =IF(I29="","",I29) -> Hauswirtschaft | AJ29: =IF(J29="","",J29) -> Entlastungsleistung | AL29: =IF(I29="Hauswirtschaft",38,42) -> 38 | AM29: =AL29*F29 -> 38 | AN29: =G29*0.35 -> 0
B30: 00012|Lothar|Krawalski | C30: 45849 | D30: 0.58333333 | E30: 0.66666667 | F30: =(E30-D30)*24 -> 2 | H30: Manuela Richter | I30: Hauswirtschaft | J30: Entlastungsleistung | K30: =VLOOKUP($B30,[1]Kundenübersicht!$E$4:$AC$1003,MATCH(K$3,[1]Kundenübersicht!$E$3:$BA$3,FALSE),FALSE) -> AOK PLUS | L30: =VLOOKUP(B30,[1]Kundenübersicht!$E$4:$AC$1003,MATCH(L$3,[1]Kundenübersicht!$E$3:$BA$3,FALSE),FALSE) -> 107299005 | M30: =VLOOKUP(B30,[1]Kundenübersicht!$E$4:$AC$1003,MATCH(M$3,[1]Kundenübersicht!$E$3:$BA$3,FALSE),FALSE) -> L212281967 | N30: =VLOOKUP(B30,[1]Kundenübersicht!$E$4:$AC$1003,MATCH(N$3,[1]Kundenübersicht!$E$3:$BA$3,FALSE),FALSE) -> PG 1 | P30: Ja | R30: Unterschrieben | S30: Link | U30: =IF(YEAR(C30)<=2025,IFERROR(IF(I30="Hauswirtschaft",VLOOKUP($B30,[1]Kundenübersicht!$E$4:$BA$1003,MATCH("Hauswirtschaft [€/Stunde]",[1]Kundenübersicht!$E$3:$BA$3,FALSE),FALSE),VLOOKUP($B30,[1]Kundenübersicht!$E$4:$BA$1003,MATCH("Alltagsbegleitung [€/Stunde]",[1]Kundenübersicht!$E$3:$BA$3,FALSE),FALSE)),0),IFERROR(IF(I30="Hauswirtschaft",VLOOKUP($B30,[1]Kundenübersicht!$E$4:$BA$1003,MATCH("HW ab 2026 [€/Stunde]",[1]Kundenübersicht!$E$3:$BA$3,FALSE),FALSE),VLOOKUP($B30,[1]Kundenübersicht!$E$4:$BA$1003,MATCH("Alltagsbegleitung [€/Stunde]",[1]Kundenübersicht!$E$3:$BA$3,FALSE),FALSE)),0)) -> 32.75 | V30: =U30*F30 -> 65.5 | W30: =IF(AND(YEAR(C30)<=2025,X30="Alt"),0,G30*0.35) -> 0 | X30: =VLOOKUP(B30,[1]Kundenübersicht!E:AG,MATCH($X$3,[1]Kundenübersicht!$E$3:$AY$3,0),FALSE) -> Alt | Z30: Ja | AC30: 45917 | AE30: =YEAR(C30) -> 2025 | AF30: =IF(MONTH(C30)<=9,"0"&MONTH(C30)&"."&YEAR(C30),MONTH(C30)&"."&YEAR(C30)) -> 07.2025 | AG30: =IF(H30="","",H30) -> Manuela Richter | AH30: =IFERROR(VLOOKUP(B30,[1]Kundenübersicht!$E$4:$F$85,2,FALSE),"") -> Lothar Krawalski | AI30: =IF(I30="","",I30) -> Hauswirtschaft | AJ30: =IF(J30="","",J30) -> Entlastungsleistung | AL30: =IF(I30="Hauswirtschaft",38,42) -> 38 | AM30: =AL30*F30 -> 76 | AN30: =G30*0.35 -> 0
B31: 00003|Günter|Marx | C31: 45852 | D31: 0.35416667 | E31: 0.4375 | F31: =(E31-D31)*24 -> 2 | H31: Christiane Fiebag | I31: Hauswirtschaft | J31: Entlastungsleistung | K31: =VLOOKUP($B31,[1]Kundenübersicht!$E$4:$AC$1003,MATCH(K$3,[1]Kundenübersicht!$E$3:$BA$3,FALSE),FALSE) -> Siemens Betriebskrankenkasse | L31: =VLOOKUP(B31,[1]Kundenübersicht!$E$4:$AC$1003,MATCH(L$3,[1]Kundenübersicht!$E$3:$BA$3,FALSE),FALSE) -> 108833505 | M31: =VLOOKUP(B31,[1]Kundenübersicht!$E$4:$AC$1003,MATCH(M$3,[1]Kundenübersicht!$E$3:$BA$3,FALSE),FALSE) -> U297967139 | N31: =VLOOKUP(B31,[1]Kundenübersicht!$E$4:$AC$1003,MATCH(N$3,[1]Kundenübersicht!$E$3:$BA$3,FALSE),FALSE) -> PG 2 | P31: Ja | R31: Unterschrieben | S31: Link | U31: =IF(YEAR(C31)<=2025,IFERROR(IF(I31="Hauswirtschaft",VLOOKUP($B31,[1]Kundenübersicht!$E$4:$BA$1003,MATCH("Hauswirtschaft [€/Stunde]",[1]Kundenübersicht!$E$3:$BA$3,FALSE),FALSE),VLOOKUP($B31,[1]Kundenübersicht!$E$4:$BA$1003,MATCH("Alltagsbegleitung [€/Stunde]",[1]Kundenübersicht!$E$3:$BA$3,FALSE),FALSE)),0),IFERROR(IF(I31="Hauswirtschaft",VLOOKUP($B31,[1]Kundenübersicht!$E$4:$BA$1003,MATCH("HW ab 2026 [€/Stunde]",[1]Kundenübersicht!$E$3:$BA$3,FALSE),FALSE),VLOOKUP($B31,[1]Kundenübersicht!$E$4:$BA$1003,MATCH("Alltagsbegleitung [€/Stunde]",[1]Kundenübersicht!$E$3:$BA$3,FALSE),FALSE)),0)) -> 32.75 | V31: =U31*F31 -> 65.5 | W31: =IF(AND(YEAR(C31)<=2025,X31="Alt"),0,G31*0.35) -> 0 | X31: =VLOOKUP(B31,[1]Kundenübersicht!E:AG,MATCH($X$3,[1]Kundenübersicht!$E$3:$AY$3,0),FALSE) -> Alt | Z31: Ja | AC31: 45959 | AE31: =YEAR(C31) -> 2025 | AF31: =IF(MONTH(C31)<=9,"0"&MONTH(C31)&"."&YEAR(C31),MONTH(C31)&"."&YEAR(C31)) -> 07.2025 | AG31: =IF(H31="","",H31) -> Christiane Fiebag | AH31: =IFERROR(VLOOKUP(B31,[1]Kundenübersicht!$E$4:$F$85,2,FALSE),"") -> Günter Marx | AI31: =IF(I31="","",I31) -> Hauswirtschaft | AJ31: =IF(J31="","",J31) -> Entlastungsleistung | AL31: =IF(I31="Hauswirtschaft",38,42) -> 38 | AM31: =AL31*F31 -> 76 | AN31: =G31*0.35 -> 0
B32: 00003|Günter|Marx | C32: 45852 | D32: 0.625 | E32: 0.66666667 | F32: =(E32-D32)*24 -> 1 | H32: Christiane Fiebag | I32: Hauswirtschaft | J32: Entlastungsleistung | K32: =VLOOKUP($B32,[1]Kundenübersicht!$E$4:$AC$1003,MATCH(K$3,[1]Kundenübersicht!$E$3:$BA$3,FALSE),FALSE) -> Siemens Betriebskrankenkasse | L32: =VLOOKUP(B32,[1]Kundenübersicht!$E$4:$AC$1003,MATCH(L$3,[1]Kundenübersicht!$E$3:$BA$3,FALSE),FALSE) -> 108833505 | M32: =VLOOKUP(B32,[1]Kundenübersicht!$E$4:$AC$1003,MATCH(M$3,[1]Kundenübersicht!$E$3:$BA$3,FALSE),FALSE) -> U297967139 | N32: =VLOOKUP(B32,[1]Kundenübersicht!$E$4:$AC$1003,MATCH(N$3,[1]Kundenübersicht!$E$3:$BA$3,FALSE),FALSE) -> PG 2 | P32: Ja | R32: Unterschrieben | S32: Link | U32: =IF(YEAR(C32)<=2025,IFERROR(IF(I32="Hauswirtschaft",VLOOKUP($B32,[1]Kundenübersicht!$E$4:$BA$1003,MATCH("Hauswirtschaft [€/Stunde]",[1]Kundenübersicht!$E$3:$BA$3,FALSE),FALSE),VLOOKUP($B32,[1]Kundenübersicht!$E$4:$BA$1003,MATCH("Alltagsbegleitung [€/Stunde]",[1]Kundenübersicht!$E$3:$BA$3,FALSE),FALSE)),0),IFERROR(IF(I32="Hauswirtschaft",VLOOKUP($B32,[1]Kundenübersicht!$E$4:$BA$1003,MATCH("HW ab 2026 [€/Stunde]",[1]Kundenübersicht!$E$3:$BA$3,FALSE),FALSE),VLOOKUP($B32,[1]Kundenübersicht!$E$4:$BA$1003,MATCH("Alltagsbegleitung [€/Stunde]",[1]Kundenübersicht!$E$3:$BA$3,FALSE),FALSE)),0)) -> 32.75 | V32: =U32*F32 -> 32.75 | W32: =IF(AND(YEAR(C32)<=2025,X32="Alt"),0,G32*0.35) -> 0 | X32: =VLOOKUP(B32,[1]Kundenübersicht!E:AG,MATCH($X$3,[1]Kundenübersicht!$E$3:$AY$3,0),FALSE) -> Alt | Z32: Ja | AC32: 45959 | AE32: =YEAR(C32) -> 2025 | AF32: =IF(MONTH(C32)<=9,"0"&MONTH(C32)&"."&YEAR(C32),MONTH(C32)&"."&YEAR(C32)) -> 07.2025 | AG32: =IF(H32="","",H32) -> Christiane Fiebag | AH32: =IFERROR(VLOOKUP(B32,[1]Kundenübersicht!$E$4:$F$85,2,FALSE),"") -> Günter Marx | AI32: =IF(I32="","",I32) -> Hauswirtschaft | AJ32: =IF(J32="","",J32) -> Entlastungsleistung | AL32: =IF(I32="Hauswirtschaft",38,42) -> 38 | AM32: =AL32*F32 -> 38 | AN32: =G32*0.35 -> 0
B33: 00006|Dieter|Berghold | C33: 45852 | D33: 0.45833333 | E33: 0.5 | F33: =(E33-D33)*24 -> 1 | H33: Christiane Fiebag | I33: Hauswirtschaft | J33: Entlastungsleistung | K33: =VLOOKUP($B33,[1]Kundenübersicht!$E$4:$AC$1003,MATCH(K$3,[1]Kundenübersicht!$E$3:$BA$3,FALSE),FALSE) -> AOK PLUS | L33: =VLOOKUP(B33,[1]Kundenübersicht!$E$4:$AC$1003,MATCH(L$3,[1]Kundenübersicht!$E$3:$BA$3,FALSE),FALSE) -> 107299005 | M33: =VLOOKUP(B33,[1]Kundenübersicht!$E$4:$AC$1003,MATCH(M$3,[1]Kundenübersicht!$E$3:$BA$3,FALSE),FALSE) -> R234942678 | N33: =VLOOKUP(B33,[1]Kundenübersicht!$E$4:$AC$1003,MATCH(N$3,[1]Kundenübersicht!$E$3:$BA$3,FALSE),FALSE) -> PG 2 | P33: Ja | R33: Unterschrieben | S33: Link | U33: =IF(YEAR(C33)<=2025,IFERROR(IF(I33="Hauswirtschaft",VLOOKUP($B33,[1]Kundenübersicht!$E$4:$BA$1003,MATCH("Hauswirtschaft [€/Stunde]",[1]Kundenübersicht!$E$3:$BA$3,FALSE),FALSE),VLOOKUP($B33,[1]Kundenübersicht!$E$4:$BA$1003,MATCH("Alltagsbegleitung [€/Stunde]",[1]Kundenübersicht!$E$3:$BA$3,FALSE),FALSE)),0),IFERROR(IF(I33="Hauswirtschaft",VLOOKUP($B33,[1]Kundenübersicht!$E$4:$BA$1003,MATCH("HW ab 2026 [€/Stunde]",[1]Kundenübersicht!$E$3:$BA$3,FALSE),FALSE),VLOOKUP($B33,[1]Kundenübersicht!$E$4:$BA$1003,MATCH("Alltagsbegleitung [€/Stunde]",[1]Kundenübersicht!$E$3:$BA$3,FALSE),FALSE)),0)) -> 32.75 | V33: =U33*F33 -> 32.75 | W33: =IF(AND(YEAR(C33)<=2025,X33="Alt"),0,G33*0.35) -> 0 | X33: =VLOOKUP(B33,[1]Kundenübersicht!E:AG,MATCH($X$3,[1]Kundenübersicht!$E$3:$AY$3,0),FALSE) -> Alt | Z33: Ja | AA33: 45950 | AC33: 45975 | AE33: =YEAR(C33) -> 2025 | AF33: =IF(MONTH(C33)<=9,"0"&MONTH(C33)&"."&YEAR(C33),MONTH(C33)&"."&YEAR(C33)) -> 07.2025 | AG33: =IF(H33="","",H33) -> Christiane Fiebag | AH33: =IFERROR(VLOOKUP(B33,[1]Kundenübersicht!$E$4:$F$85,2,FALSE),"") -> Dieter Berghold | AI33: =IF(I33="","",I33) -> Hauswirtschaft | AJ33: =IF(J33="","",J33) -> Entlastungsleistung | AL33: =IF(I33="Hauswirtschaft",38,42) -> 38 | AM33: =AL33*F33 -> 38 | AN33: =G33*0.35 -> 0
